Workbook

Sheet Magaza_Adres
A1: MağazaID | B1: Mağaza | C1: Adres | D1: Enlem | E1: Boylam | F1: Veri Durumu
A2: M001 | B2: AKEVLER | C2: VATAN MAH. FARUK AKAR KARASU CAD. NO:66-70 KARABAĞLAR /İZMİR | D2: 38.394301 | E2: 27.105194 | F2: Gerçek - Google Places
A3: M002 | B3: AYDIN EFELER | C3: EFELER MAH.MEVLANA CAD.NO:18/B-18 EFELER/AYDIN | D3: 37.838459 | E3: 27.823758 | F3: Gerçek - Google Places
A4: M003 | B4: AYDIN EFELER-2 | C4: EFELER MAH. | D4: 37.842863 | E4: 27.828212 | F4: Gerçek - Google Places
A5: M004 | B5: AYDIN FATİH | C5: FATİH MAH.ÇİNE CAD NO:42/44 AYDIN/FATİH | D5: 37.834436 | E5: 27.837138 | F5: Gerçek - Google Places
A6: M005 | B6: AYDIN FATİH-2 | C6: FATİH MAH. AYDIN SOKAK NO:69/A FATİH/AYDIN | D6: 37.839908 | E6: 27.845862 | F6: Gerçek - Google Places
A7: M006 | B7: AYDIN GİRNE | C7: GİRNE MAH. TURGUT ÖZAL BULVARI NO:17/13 EFELER/AYDIN | D7: 37.857618 | E7: 27.823128 | F7: Gerçek - Google Places
A8: M007 | B8: AYDIN MİMARSİNAN | C8: MİMARSİNAN MAH.ALİ İHSAN PAŞA BULV. NO:19/A EFELER/AYDIN | D8: 37.851048 | E8: 27.817409 | F8: Gerçek - Google Places
A9: M008 | B9: AYRANCILAR | C9: FEVZİ ÇAKMAK MAH.BARIŞ MANÇO CAD.NO:26/22 AYRANCILAR/İZMİR | D9: 38.240289 | E9: 27.281412 | F9: Gerçek - Google Places
A10: M009 | B10: BALÇOVA | C10: FEVZİ ÇAKMAK MAH.SAKARYA CAD.NO:12 BALÇOVA/İZMİR | D10: 38.385072 | E10: 27.057448 | F10: Gerçek - Google Places
A11: M010 | B11: BAYRAKLI | C11: SOĞUKKUYU MAH. 1846 SOK. NO:8/B BAYRAKLI/ İZMİR | D11: 38.471686 | E11: 27.11778 | F11: Gerçek - Google Places
A12: M011 | B12: BOZYAKA | C12: BAHÇELİEVLER MH.SAİM ÇIKRIKÇI CD.NO:120 / A-B KARABAĞLAR / İZMİR | D12: 38.397598 | E12: 27.122202 | F12: Gerçek - Google Places
A13: M012 | B13: BUCA | C13: FIRAT MAH.647/16 SOK.NO:6/A BUCA/İZMİR | D13: 38.373039 | E13: 27.150591 | F13: Gerçek - Google Places
... A25: M024 | B25: GÜMÜŞPALA | C25: GÜMÜŞPALA MH.7020 SK NO:40/1 BAYRAKLI / İZMİR | D25: 38.469293 | E25: 27.136971 | F25: Gerçek - Google Places
A26: M025 | B26: HAL DEPO | D26: 38.412 | E26: 27.168 | F26: Dummy - Adres bilgisi yok, elle girilmeli
A27: M026 | B27: HARMANDALI | C27: BALATÇIK MAH. 8790/5 SOK. NO:4 ÇİĞLİ/İZMİR | D27: 38.519644 | E27: 27.041157 | F27: Gerçek - Google Places
A28: M027 | B28: HATAY | C28: BASIN SİTESİ MAH. İNÖNÜ CAD. NO:403/A KARABAGLAR | D28: 38.401482 | E28: 27.101156 | F28: Gerçek - Google Places
A29: M028 | B29: KARŞIYAKA-1 | C29: BAHÇELİEVLER MAH.RÜŞTÜ ŞARDAĞ CAD.NO:22/1A KARŞIYAKA/İZMİR | D29: 38.465171 | E29: 27.111266 | F29: Gerçek - Google Places
A30: M029 | B30: KARŞIYAKA-2 | C30: İMBATLI MAH.6076 SOK.NO:14/A KARŞIYAKA/İZMİR | D30: 38.474585 | E30: 27.113885 | F30: Gerçek - Google Places
A31: M030 | B31: MANAVKUYU | C31: MANAVKUYU MAH.ŞEHİT PİLOT ÜST.TÜRKER AYDIN SOK.NO:123/A BAYRAKLI/İZMİR | D31: 38.462571 | E31: 27.182404 | F31: Gerçek - Google Places (Başdaş Market Manavkuyu, No:123/A eşleşti)
A32: M031 | B32: MENDERES | C32: KASIMPAŞA MAH.250 SK. NO.13 MENDERES /İZMİR | D32: 38.260463 | E32: 27.125587 | F32: Gerçek - Google Places
A33: M032 | B33: MENDERES DEPO | D33: 38.441 | E33: 27.072 | F33: Dummy - Adres bilgisi yok, elle girilmeli
A34: M033 | B34: MERKEZ | D34: 38.438 | E34: 27.328 | F34: Dummy - Adres bilgisi yok, elle girilmeli
A35: M034 | B35: NARLIDERE | C35: NARLI MAH.İSMET İNÖNÜ CAD. NO:30/A NARLIDERE/İZMİR | D35: 38.392816 | E35: 27.006006 | F35: Gerçek - Google Places
A36: M035 | B36: OSMANGAZİ | C36: OSMANGAZİ MAH.DUMLUPINAR CAD.NO:67/C BAYRAKLI/İZMİR | D36: 38.464877 | E36: 27.194834 | F36: Gerçek - Google Places
A37: M036 | B37: POLİGON | C37: MUAMMER AKAR MH.İNÖNÜ CD.NO:817/A KARABAĞLAR / İZMİR | D37: 38.395182 | E37: 27.075087 | F37: Gerçek - Google Places
A38: M037 | B38: SEFERİHİSAR | C38: CAMİKEBİR MH.ATATÜRK CD NO:63/A SEFERİHİSAR / İZMİR | D38: 38.194921 | E38: 26.835212 | F38: Gerçek - Google Places
A39: M038 | B39: TORBALI 1 | C39: ERTUĞRUL MAH.KAZIM DİRİK CAD.NO:78 TORBALI/İZMİR | D39: 38.154917 | E39: 27.36151 | F39: Gerçek - Google Places
A40: M039 | B40: TORBALI 2 | C40: ALPKENT MAH. CEMALİ TUNCER BUL. NO:24/23 TORBALI/İZMİR | D40: 38.164664 | E40: 27.356116 | F40: Gerçek - Google Places
A41: M040 | B41: TORBALI 3 | C41: MURATBEY MAH.İBRAHİM KESİCİ CAD.NO:6/1A TORBALI/İZMİR | D41: 38.14881 | E41: 27.356671 | F41: Gerçek - Google Places
A42: M041 | B42: TORBALI 4 | C42: MURAT BEY MAH. DOĞAN BURSALIOĞLU CAD. NO:5/A TORBALI-İZMİR | D42: 38.151657 | E42: 27.353193 | F42: Gerçek - Google Places
A43: M042 | B43: TORBALI 5 | C43: TORBALI MAH. 5046 SOK. NO:1/A A BLOK 21 NO.LU DÜKKAN TORBALI-İZMİR | D43: 38.171353 | E43: 27.349829 | F43: Gerçek - Google Places
A44: M043 | B44: YAPICIOĞLU | C44: DOLAPLIKUYU MAH.RAKIM ERKUTLU CAD.NO:157 YAPICIOĞLU-KONAK/İZMİR | D44: 38.41192 | E44: 27.135689 | F44: Gerçek - Google Places
A45: M044 | B45: YEŞİLOVA | C45: YEŞİLOVA MAH. 4053 SOK. NO:94/A BORNOVA/İZMİR | D45: 38.436005 | E45: 27.206807 | F45: Gerçek - Google Places
A46: M045 | B46: Z1 ET DEPO | D46: 38.49 | E46: 27.072 | F46: Dummy - Adres bilgisi yok, elle girilmeli
A47: M046 | B47: ÇAMDİBİ | C47: RAFET PAŞA MAH.5329 SK NO:45/A BORNOVA/İZMİR | D47: 38.438109 | E47: 27.19608 | F47: Gerçek - Google Places
A48: M047 | B48: ÇİFTLİK | D48: 38.496 | E48: 27.136 | F48: Dummy - Adres bilgisi yok, elle girilmeli
A49: M048 | B49: ÇİĞLİ | C49: ATAŞEHİR MAH. ESKİ HAVAALANI CAD. NO:69/A ÇİĞLİ-İZMİR | D49: 38.493071 | E49: 27.054551 | F49: Gerçek - Google Places
A50: M049 | B50: ÖZDERE | C50: ÇUKURALTI MAH. MUSTAFA KEMAL PAŞA BULVARI NO:237/C ÖZDERE/İZMİR | D50: 38.021894 | E50: 27.092563 | F50: Gerçek - Google Places
A51: M050 | B51: İZMİRSPOR | C51: BAHÇELİEVLER MH.490 SK.NO:2/1 KARABAĞLAR / İZMİR | D51: 38.403691 | E51: 27.119105 | F51: Gerçek - Google Places
...

Sheet Fact_Norm
A1: MağazaID | B1: Mağaza | C1: Bölge Sorumlusu | D1: UnvanID | E1: Unvan | F1: Norm Kadro
A2: M001 | B2: =IFERROR(VLOOKUP(A2,Dim_Magaza!$A:$C,2,FALSE()),"") | C2: =IFERROR(VLOOKUP(A2,Dim_Magaza!$A:$C,3,FALSE()),"") | D2: U002 | E2: =IFERROR(VLOOKUP(D2,Dim_Unvan!$A:$B,2,FALSE()),"") | F2: 1
A3: M001 | B3: =IFERROR(VLOOKUP(A3,Dim_Magaza!$A:$C,2,FALSE()),"") | C3: =IFERROR(VLOOKUP(A3,Dim_Magaza!$A:$C,3,FALSE()),"") | D3: U013 | E3: =IFERROR(VLOOKUP(D3,Dim_Unvan!$A:$B,2,FALSE()),"") | F3: 1
A4: M001 | B4: =IFERROR(VLOOKUP(A4,Dim_Magaza!$A:$C,2,FALSE()),"") | C4: =IFERROR(VLOOKUP(A4,Dim_Magaza!$A:$C,3,FALSE()),"") | D4: U015 | E4: =IFERROR(VLOOKUP(D4,Dim_Unvan!$A:$B,2,FALSE()),"") | F4: 3
A5: M001 | B5: =IFERROR(VLOOKUP(A5,Dim_Magaza!$A:$C,2,FALSE()),"") | C5: =IFERROR(VLOOKUP(A5,Dim_Magaza!$A:$C,3,FALSE()),"") | D5: U017 | E5: =IFERROR(VLOOKUP(D5,Dim_Unvan!$A:$B,2,FALSE()),"") | F5: 2
A6: M001 | B6: =IFERROR(VLOOKUP(A6,Dim_Magaza!$A:$C,2,FALSE()),"") | C6: =IFERROR(VLOOKUP(A6,Dim_Magaza!$A:$C,3,FALSE()),"") | D6: U023 | E6: =IFERROR(VLOOKUP(D6,Dim_Unvan!$A:$B,2,FALSE()),"") | F6: 1
A7: M001 | B7: =IFERROR(VLOOKUP(A7,Dim_Magaza!$A:$C,2,FALSE()),"") | C7: =IFERROR(VLOOKUP(A7,Dim_Magaza!$A:$C,3,FALSE()),"") | D7: U024 | E7: =IFERROR(VLOOKUP(D7,Dim_Unvan!$A:$B,2,FALSE()),"") | F7: 1
A8: M001 | B8: =IFERROR(VLOOKUP(A8,Dim_Magaza!$A:$C,2,FALSE()),"") | C8: =IFERROR(VLOOKUP(A8,Dim_Magaza!$A:$C,3,FALSE()),"") | D8: U026 | E8: =IFERROR(VLOOKUP(D8,Dim_Unvan!$A:$B,2,FALSE()),"") | F8: 2
A9: M001 | B9: =IFERROR(VLOOKUP(A9,Dim_Magaza!$A:$C,2,FALSE()),"") | C9: =IFERROR(VLOOKUP(A9,Dim_Magaza!$A:$C,3,FALSE()),"") | D9: U036 | E9: =IFERROR(VLOOKUP(D9,Dim_Unvan!$A:$B,2,FALSE()),"") | F9: 1
A10: M001 | B10: =IFERROR(VLOOKUP(A10,Dim_Magaza!$A:$C,2,FALSE()),"") | C10: =IFERROR(VLOOKUP(A10,Dim_Magaza!$A:$C,3,FALSE()),"") | D10: U038 | E10: =IFERROR(VLOOKUP(D10,Dim_Unvan!$A:$B,2,FALSE()),"") | F10: 1
A11: M001 | B11: =IFERROR(VLOOKUP(A11,Dim_Magaza!$A:$C,2,FALSE()),"") | C11: =IFERROR(VLOOKUP(A11,Dim_Magaza!$A:$C,3,FALSE()),"") | D11: U042 | E11: =IFERROR(VLOOKUP(D11,Dim_Unvan!$A:$B,2,FALSE()),"") | F11: 1
A12: M002 | B12: =IFERROR(VLOOKUP(A12,Dim_Magaza!$A:$C,2,FALSE()),"") | C12: =IFERROR(VLOOKUP(A12,Dim_Magaza!$A:$C,3,FALSE()),"") | D12: U002 | E12: =IFERROR(VLOOKUP(D12,Dim_Unvan!$A:$B,2,FALSE()),"") | F12: 1
A13: M002 | B13: =IFERROR(VLOOKUP(A13,Dim_Magaza!$A:$C,2,FALSE()),"") | C13: =IFERROR(VLOOKUP(A13,Dim_Magaza!$A:$C,3,FALSE()),"") | D13: U013 | E13: =IFERROR(VLOOKUP(D13,Dim_Unvan!$A:$B,2,FALSE()),"") | F13: 1
... A74: M008 | B74: =IFERROR(VLOOKUP(A74,Dim_Magaza!$A:$C,2,FALSE()),"") | C74: =IFERROR(VLOOKUP(A74,Dim_Magaza!$A:$C,3,FALSE()),"") | D74: U042 | E74: =IFERROR(VLOOKUP(D74,Dim_Unvan!$A:$B,2,FALSE()),"") | F74: 1
A75: M008 | B75: =IFERROR(VLOOKUP(A75,Dim_Magaza!$A:$C,2,FALSE()),"") | C75: =IFERROR(VLOOKUP(A75,Dim_Magaza!$A:$C,3,FALSE()),"") | D75: U034 | E75: UNLU MAMÜLLER | F75: 1
A76: M009 | B76: =IFERROR(VLOOKUP(A76,Dim_Magaza!$A:$C,2,FALSE()),"") | C76: =IFERROR(VLOOKUP(A76,Dim_Magaza!$A:$C,3,FALSE()),"") | D76: U002 | E76: =IFERROR(VLOOKUP(D76,Dim_Unvan!$A:$B,2,FALSE()),"") | F76: 1
A77: M009 | B77: =IFERROR(VLOOKUP(A77,Dim_Magaza!$A:$C,2,FALSE()),"") | C77: =IFERROR(VLOOKUP(A77,Dim_Magaza!$A:$C,3,FALSE()),"") | D77: U013 | E77: =IFERROR(VLOOKUP(D77,Dim_Unvan!$A:$B,2,FALSE()),"") | F77: 1
A78: M009 | B78: =IFERROR(VLOOKUP(A78,Dim_Magaza!$A:$C,2,FALSE()),"") | C78: =IFERROR(VLOOKUP(A78,Dim_Magaza!$A:$C,3,FALSE()),"") | D78: U014 | E78: =IFERROR(VLOOKUP(D78,Dim_Unvan!$A:$B,2,FALSE()),"") | F78: 1
A79: M009 | B79: =IFERROR(VLOOKUP(A79,Dim_Magaza!$A:$C,2,FALSE()),"") | C79: =IFERROR(VLOOKUP(A79,Dim_Magaza!$A:$C,3,FALSE()),"") | D79: U015 | E79: =IFERROR(VLOOKUP(D79,Dim_Unvan!$A:$B,2,FALSE()),"") | F79: 4
A80: M009 | B80: =IFERROR(VLOOKUP(A80,Dim_Magaza!$A:$C,2,FALSE()),"") | C80: =IFERROR(VLOOKUP(A80,Dim_Magaza!$A:$C,3,FALSE()),"") | D80: U017 | E80: =IFERROR(VLOOKUP(D80,Dim_Unvan!$A:$B,2,FALSE()),"") | F80: 2
A81: M009 | B81: =IFERROR(VLOOKUP(A81,Dim_Magaza!$A:$C,2,FALSE()),"") | C81: =IFERROR(VLOOKUP(A81,Dim_Magaza!$A:$C,3,FALSE()),"") | D81: U018 | E81: =IFERROR(VLOOKUP(D81,Dim_Unvan!$A:$B,2,FALSE()),"") | F81: 1
A82: M009 | B82: =IFERROR(VLOOKUP(A82,Dim_Magaza!$A:$C,2,FALSE()),"") | C82: =IFERROR(VLOOKUP(A82,Dim_Magaza!$A:$C,3,FALSE()),"") | D82: U019 | E82: =IFERROR(VLOOKUP(D82,Dim_Unvan!$A:$B,2,FALSE()),"") | F82: 2
A83: M009 | B83: =IFERROR(VLOOKUP(A83,Dim_Magaza!$A:$C,2,FALSE()),"") | C83: =IFERROR(VLOOKUP(A83,Dim_Magaza!$A:$C,3,FALSE()),"") | D83: U023 | E83: =IFERROR(VLOOKUP(D83,Dim_Unvan!$A:$B,2,FALSE()),"") | F83: 1
A84: M009 | B84: =IFERROR(VLOOKUP(A84,Dim_Magaza!$A:$C,2,FALSE()),"") | C84: =IFERROR(VLOOKUP(A84,Dim_Magaza!$A:$C,3,FALSE()),"") | D84: U024 | E84: =IFERROR(VLOOKUP(D84,Dim_Unvan!$A:$B,2,FALSE()),"") | F84: 1
A85: M009 | B85: =IFERROR(VLOOKUP(A85,Dim_Magaza!$A:$C,2,FALSE()),"") | C85: =IFERROR(VLOOKUP(A85,Dim_Magaza!$A:$C,3,FALSE()),"") | D85: U026 | E85: =IFERROR(VLOOKUP(D85,Dim_Unvan!$A:$B,2,FALSE()),"") | F85: 3
A86: M009 | B86: =IFERROR(VLOOKUP(A86,Dim_Magaza!$A:$C,2,FALSE()),"") | C86: =IFERROR(VLOOKUP(A86,Dim_Magaza!$A:$C,3,FALSE()),"") | D86: U036 | E86: =IFERROR(VLOOKUP(D86,Dim_Unvan!$A:$B,2,FALSE()),"") | F86: 1
A87: M009 | B87: =IFERROR(VLOOKUP(A87,Dim_Magaza!$A:$C,2,FALSE()),"") | C87: =IFERROR(VLOOKUP(A87,Dim_Magaza!$A:$C,3,FALSE()),"") | D87: U038 | E87: =IFERROR(VLOOKUP(D87,Dim_Unvan!$A:$B,2,FALSE()),"") | F87: 2
... A264: M031 | B264: =IFERROR(VLOOKUP(A264,Dim_Magaza!$A:$C,2,FALSE()),"") | C264: =IFERROR(VLOOKUP(A264,Dim_Magaza!$A:$C,3,FALSE()),"") | D264: U042 | E264: =IFERROR(VLOOKUP(D264,Dim_Unvan!$A:$B,2,FALSE()),"") | F264: 1
A265: M031 | B265: =IFERROR(VLOOKUP(A265,Dim_Magaza!$A:$C,2,FALSE()),"") | C265: =IFERROR(VLOOKUP(A265,Dim_Magaza!$A:$C,3,FALSE()),"") | D265: U059 | E265: PART TİME | F265: 1
A266: M034 | B266: =IFERROR(VLOOKUP(A266,Dim_Magaza!$A:$C,2,FALSE()),"") | C266: =IFERROR(VLOOKUP(A266,Dim_Magaza!$A:$C,3,FALSE()),"") | D266: U002 | E266: =IFERROR(VLOOKUP(D266,Dim_Unvan!$A:$B,2,FALSE()),"") | F266: 1
A267: M034 | B267: =IFERROR(VLOOKUP(A267,Dim_Magaza!$A:$C,2,FALSE()),"") | C267: =IFERROR(VLOOKUP(A267,Dim_Magaza!$A:$C,3,FALSE()),"") | D267: U013 | E267: =IFERROR(VLOOKUP(D267,Dim_Unvan!$A:$B,2,FALSE()),"") | F267: 1
A268: M034 | B268: =IFERROR(VLOOKUP(A268,Dim_Magaza!$A:$C,2,FALSE()),"") | C268: =IFERROR(VLOOKUP(A268,Dim_Magaza!$A:$C,3,FALSE()),"") | D268: U015 | E268: =IFERROR(VLOOKUP(D268,Dim_Unvan!$A:$B,2,FALSE()),"") | F268: 2
A269: M034 | B269: =IFERROR(VLOOKUP(A269,Dim_Magaza!$A:$C,2,FALSE()),"") | C269: =IFERROR(VLOOKUP(A269,Dim_Magaza!$A:$C,3,FALSE()),"") | D269: U017 | E269: =IFERROR(VLOOKUP(D269,Dim_Unvan!$A:$B,2,FALSE()),"") | F269: 2
A270: M034 | B270: =IFERROR(VLOOKUP(A270,Dim_Magaza!$A:$C,2,FALSE()),"") | C270: =IFERROR(VLOOKUP(A270,Dim_Magaza!$A:$C,3,FALSE()),"") | D270: U026 | E270: =IFERROR(VLOOKUP(D270,Dim_Unvan!$A:$B,2,FALSE()),"") | F270: 2
A271: M034 | B271: =IFERROR(VLOOKUP(A271,Dim_Magaza!$A:$C,2,FALSE()),"") | C271: =IFERROR(VLOOKUP(A271,Dim_Magaza!$A:$C,3,FALSE()),"") | D271: U036 | E271: =IFERROR(VLOOKUP(D271,Dim_Unvan!$A:$B,2,FALSE()),"") | F271: 1
A272: M034 | B272: =IFERROR(VLOOKUP(A272,Dim_Magaza!$A:$C,2,FALSE()),"") | C272: =IFERROR(VLOOKUP(A272,Dim_Magaza!$A:$C,3,FALSE()),"") | D272: U038 | E272: =IFERROR(VLOOKUP(D272,Dim_Unvan!$A:$B,2,FALSE()),"") | F272: 1
A273: M034 | B273: =IFERROR(VLOOKUP(A273,Dim_Magaza!$A:$C,2,FALSE()),"") | C273: =IFERROR(VLOOKUP(A273,Dim_Magaza!$A:$C,3,FALSE()),"") | D273: U042 | E273: =IFERROR(VLOOKUP(D273,Dim_Unvan!$A:$B,2,FALSE()),"") | F273: 1
A274: M035 | B274: =IFERROR(VLOOKUP(A274,Dim_Magaza!$A:$C,2,FALSE()),"") | C274: =IFERROR(VLOOKUP(A274,Dim_Magaza!$A:$C,3,FALSE()),"") | D274: U002 | E274: =IFERROR(VLOOKUP(D274,Dim_Unvan!$A:$B,2,FALSE()),"") | F274: 1
A275: M035 | B275: =IFERROR(VLOOKUP(A275,Dim_Magaza!$A:$C,2,FALSE()),"") | C275: =IFERROR(VLOOKUP(A275,Dim_Magaza!$A:$C,3,FALSE()),"") | D275: U013 | E275: =IFERROR(VLOOKUP(D275,Dim_Unvan!$A:$B,2,FALSE()),"") | F275: 1
A276: M035 | B276: =IFERROR(VLOOKUP(A276,Dim_Magaza!$A:$C,2,FALSE()),"") | C276: =IFERROR(VLOOKUP(A276,Dim_Magaza!$A:$C,3,FALSE()),"") | D276: U015 | E276: =IFERROR(VLOOKUP(D276,Dim_Unvan!$A:$B,2,FALSE()),"") | F276: 2
...

Sheet Fact_Mevcut
A1: MağazaID | B1: Mağaza | C1: Bölge Sorumlusu | D1: UnvanID | E1: Unvan | F1: Departman | G1: Norm fazlası Norm eksiği | H1: Açıklama | I1: İsim Soyisim | J1: İşe Giriş | K1: İşten Çıkış | L1: Çıkış Kodu | M1: CikisNedeniID | N1: Çıkış Nedeni | O1: Durum | P1: Kıdem (Gün) | Q1: Kıdem (Yıl)
A2: M038 | B2: =IFERROR(VLOOKUP(A2,Dim_Magaza!$A:$C,2,FALSE()),"") | C2: =IFERROR(VLOOKUP(A2,Dim_Magaza!$A:$C,3,FALSE()),"") | D2: U036 | E2: =IFERROR(VLOOKUP(D2,Dim_Unvan!$A:$B,2,FALSE()),"") | F2: YÖNETİCİ | G2: =IF(OR(A2="",F2="",I2="",K2<>""),"",IF(COUNTIFS($A$2:A2,A2,$F$2:F2,F2,$K$2:K2,"")<=SUMIFS(REFERENTIAL_CONTROL!$K:$K,REFERENTIAL_CONTROL!$H:$H,A2,REFERENTIAL_CONTROL!$I:$I,IFERROR(INDEX(Dim_Unvan!$A:$A,MATCH(F2,Dim_Unvan!$B:$B,0)),"")),"Norm Fazlası","Norma Uygun")) | I2: ŞEYMA ASLAN | J2: 43367 | N2: =IFERROR(VLOOKUP(M2,Dim_CikisNedeni!$A:$B,2,FALSE()),"") | O2: =IF(I2="","",IF(K2<>"","Pasif","Aktif")) | P2: =IF(J2="","",IF(K2<>"",K2-J2,TODAY()-J2)) | Q2: =IF(P2="","",ROUND(P2/365,1))
A3: M038 | B3: =IFERROR(VLOOKUP(A3,Dim_Magaza!$A:$C,2,FALSE()),"") | C3: =IFERROR(VLOOKUP(A3,Dim_Magaza!$A:$C,3,FALSE()),"") | D3: U015 | E3: =IFERROR(VLOOKUP(D3,Dim_Unvan!$A:$B,2,FALSE()),"") | F3: KASİYER | G3: =IF(OR(A3="",F3="",I3="",K3<>""),"",IF(COUNTIFS($A$2:A3,A3,$F$2:F3,F3,$K$2:K3,"")<=SUMIFS(REFERENTIAL_CONTROL!$K:$K,REFERENTIAL_CONTROL!$H:$H,A3,REFERENTIAL_CONTROL!$I:$I,IFERROR(INDEX(Dim_Unvan!$A:$A,MATCH(F3,Dim_Unvan!$B:$B,0)),"")),"Norm Fazlası","Norma Uygun")) | I3: KEVSER ARSLAN | N3: =IFERROR(VLOOKUP(M3,Dim_CikisNedeni!$A:$B,2,FALSE()),"") | O3: =IF(I3="","",IF(K3<>"","Pasif","Aktif")) | P3: =IF(J3="","",IF(K3<>"",K3-J3,TODAY()-J3)) | Q3: =IF(P3="","",ROUND(P3/365,1))
A4: M038 | B4: =IFERROR(VLOOKUP(A4,Dim_Magaza!$A:$C,2,FALSE()),"") | C4: =IFERROR(VLOOKUP(A4,Dim_Magaza!$A:$C,3,FALSE()),"") | D4: U015 | E4: =IFERROR(VLOOKUP(D4,Dim_Unvan!$A:$B,2,FALSE()),"") | F4: KASİYER | G4: =IF(OR(A4="",F4="",I4="",K4<>""),"",IF(COUNTIFS($A$2:A4,A4,$F$2:F4,F4,$K$2:K4,"")<=SUMIFS(REFERENTIAL_CONTROL!$K:$K,REFERENTIAL_CONTROL!$H:$H,A4,REFERENTIAL_CONTROL!$I:$I,IFERROR(INDEX(Dim_Unvan!$A:$A,MATCH(F4,Dim_Unvan!$B:$B,0)),"")),"Norm Fazlası","Norma Uygun")) | I4: BİLGE AKŞİT | N4: =IFERROR(VLOOKUP(M4,Dim_CikisNedeni!$A:$B,2,FALSE()),"") | O4: =IF(I4="","",IF(K4<>"","Pasif","Aktif")) | P4: =IF(J4="","",IF(K4<>"",K4-J4,TODAY()-J4)) | Q4: =IF(P4="","",ROUND(P4/365,1))
A5: M038 | B5: =IFERROR(VLOOKUP(A5,Dim_Magaza!$A:$C,2,FALSE()),"") | C5: =IFERROR(VLOOKUP(A5,Dim_Magaza!$A:$C,3,FALSE()),"") | D5: U015 | E5: =IFERROR(VLOOKUP(D5,Dim_Unvan!$A:$B,2,FALSE()),"") | F5: KASİYER | G5: =IF(OR(A5="",F5="",I5="",K5<>""),"",IF(COUNTIFS($A$2:A5,A5,$F$2:F5,F5,$K$2:K5,"")<=SUMIFS(REFERENTIAL_CONTROL!$K:$K,REFERENTIAL_CONTROL!$H:$H,A5,REFERENTIAL_CONTROL!$I:$I,IFERROR(INDEX(Dim_Unvan!$A:$A,MATCH(F5,Dim_Unvan!$B:$B,0)),"")),"Norm Fazlası","Norma Uygun")) | I5: EVİN MEN | N5: =IFERROR(VLOOKUP(M5,Dim_CikisNedeni!$A:$B,2,FALSE()),"") | O5: =IF(I5="","",IF(K5<>"","Pasif","Aktif")) | P5: =IF(J5="","",IF(K5<>"",K5-J5,TODAY()-J5)) | Q5: =IF(P5="","",ROUND(P5/365,1))
A6: M038 | B6: =IFERROR(VLOOKUP(A6,Dim_Magaza!$A:$C,2,FALSE()),"") | C6: =IFERROR(VLOOKUP(A6,Dim_Magaza!$A:$C,3,FALSE()),"") | D6: U026 | E6: =IFERROR(VLOOKUP(D6,Dim_Unvan!$A:$B,2,FALSE()),"") | F6: REYON GÖREVLİSİ | G6: =IF(OR(A6="",F6="",I6="",K6<>""),"",IF(COUNTIFS($A$2:A6,A6,$F$2:F6,F6,$K$2:K6,"")<=SUMIFS(REFERENTIAL_CONTROL!$K:$K,REFERENTIAL_CONTROL!$H:$H,A6,REFERENTIAL_CONTROL!$I:$I,IFERROR(INDEX(Dim_Unvan!$A:$A,MATCH(F6,Dim_Unvan!$B:$B,0)),"")),"Norm Fazlası","Norma Uygun")) | I6: AYBEK SAPAYEV | N6: =IFERROR(VLOOKUP(M6,Dim_CikisNedeni!$A:$B,2,FALSE()),"") | O6: =IF(I6="","",IF(K6<>"","Pasif","Aktif")) | P6: =IF(J6="","",IF(K6<>"",K6-J6,TODAY()-J6)) | Q6: =IF(P6="","",ROUND(P6/365,1))
A7: M038 | B7: =IFERROR(VLOOKUP(A7,Dim_Magaza!$A:$C,2,FALSE()),"") | C7: =IFERROR(VLOOKUP(A7,Dim_Magaza!$A:$C,3,FALSE()),"") | D7: U026 | E7: =IFERROR(VLOOKUP(D7,Dim_Unvan!$A:$B,2,FALSE()),"") | F7: REYON GÖREVLİSİ | G7: =IF(OR(A7="",F7="",I7="",K7<>""),"",IF(COUNTIFS($A$2:A7,A7,$F$2:F7,F7,$K$2:K7,"")<=SUMIFS(REFERENTIAL_CONTROL!$K:$K,REFERENTIAL_CONTROL!$H:$H,A7,REFERENTIAL_CONTROL!$I:$I,IFERROR(INDEX(Dim_Unvan!$A:$A,MATCH(F7,Dim_Unvan!$B:$B,0)),"")),"Norm Fazlası","Norma Uygun")) | I7: SHIHNAZAR DURDYBAYEV | N7: =IFERROR(VLOOKUP(M7,Dim_CikisNedeni!$A:$B,2,FALSE()),"") | O7: =IF(I7="","",IF(K7<>"","Pasif","Aktif")) | P7: =IF(J7="","",IF(K7<>"",K7-J7,TODAY()-J7)) | Q7: =IF(P7="","",ROUND(P7/365,1))
A8: M038 | B8: =IFERROR(VLOOKUP(A8,Dim_Magaza!$A:$C,2,FALSE()),"") | C8: =IFERROR(VLOOKUP(A8,Dim_Magaza!$A:$C,3,FALSE()),"") | D8: U002 | E8: =IFERROR(VLOOKUP(D8,Dim_Unvan!$A:$B,2,FALSE()),"") | F8: BAKLİYAT | G8: =IF(OR(A8="",F8="",I8="",K8<>""),"",IF(COUNTIFS($A$2:A8,A8,$F$2:F8,F8,$K$2:K8,"")<=SUMIFS(REFERENTIAL_CONTROL!$K:$K,REFERENTIAL_CONTROL!$H:$H,A8,REFERENTIAL_CONTROL!$I:$I,IFERROR(INDEX(Dim_Unvan!$A:$A,MATCH(F8,Dim_Unvan!$B:$B,0)),"")),"Norm Fazlası","Norma Uygun")) | I8: HİLAL SEVİNÇ | N8: =IFERROR(VLOOKUP(M8,Dim_CikisNedeni!$A:$B,2,FALSE()),"") | O8: =IF(I8="","",IF(K8<>"","Pasif","Aktif")) | P8: =IF(J8="","",IF(K8<>"",K8-J8,TODAY()-J8)) | Q8: =IF(P8="","",ROUND(P8/365,1))
A9: M038 | B9: =IFERROR(VLOOKUP(A9,Dim_Magaza!$A:$C,2,FALSE()),"") | C9: =IFERROR(VLOOKUP(A9,Dim_Magaza!$A:$C,3,FALSE()),"") | D9: U050 | E9: =IFERROR(VLOOKUP(D9,Dim_Unvan!$A:$B,2,FALSE()),"") | F9: ŞARKÜTERİ | G9: =IF(OR(A9="",F9="",I9="",K9<>""),"",IF(COUNTIFS($A$2:A9,A9,$F$2:F9,F9,$K$2:K9,"")<=SUMIFS(REFERENTIAL_CONTROL!$K:$K,REFERENTIAL_CONTROL!$H:$H,A9,REFERENTIAL_CONTROL!$I:$I,IFERROR(INDEX(Dim_Unvan!$A:$A,MATCH(F9,Dim_Unvan!$B:$B,0)),"")),"Norm Fazlası","Norma Uygun")) | I9: GÜLER DURMAZ | N9: =IFERROR(VLOOKUP(M9,Dim_CikisNedeni!$A:$B,2,FALSE()),"") | O9: =IF(I9="","",IF(K9<>"","Pasif","Aktif")) | P9: =IF(J9="","",IF(K9<>"",K9-J9,TODAY()-J9)) | Q9: =IF(P9="","",ROUND(P9/365,1))
A10: M038 | B10: =IFERROR(VLOOKUP(A10,Dim_Magaza!$A:$C,2,FALSE()),"") | C10: =IFERROR(VLOOKUP(A10,Dim_Magaza!$A:$C,3,FALSE()),"") | D10: U053 | E10: =IFERROR(VLOOKUP(D10,Dim_Unvan!$A:$B,2,FALSE()),"") | F10: KASAP | G10: =IF(OR(A10="",F10="",I10="",K10<>""),"",IF(COUNTIFS($A$2:A10,A10,$F$2:F10,F10,$K$2:K10,"")<=SUMIFS(REFERENTIAL_CONTROL!$K:$K,REFERENTIAL_CONTROL!$H:$H,A10,REFERENTIAL_CONTROL!$I:$I,IFERROR(INDEX(Dim_Unvan!$A:$A,MATCH(F10,Dim_Unvan!$B:$B,0)),"")),"Norm Fazlası","Norma Uygun")) | I10: HÜSEYİN EMİR KARAYILAN | N10: =IFERROR(VLOOKUP(M10,Dim_CikisNedeni!$A:$B,2,FALSE()),"") | O10: =IF(I10="","",IF(K10<>"","Pasif","Aktif")) | P10: =IF(J10="","",IF(K10<>"",K10-J10,TODAY()-J10)) | Q10: =IF(P10="","",ROUND(P10/365,1))
A11: M038 | B11: =IFERROR(VLOOKUP(A11,Dim_Magaza!$A:$C,2,FALSE()),"") | C11: =IFERROR(VLOOKUP(A11,Dim_Magaza!$A:$C,3,FALSE()),"") | D11: U051 | E11: =IFERROR(VLOOKUP(D11,Dim_Unvan!$A:$B,2,FALSE()),"") | F11: MANAV | G11: =IF(OR(A11="",F11="",I11="",K11<>""),"",IF(COUNTIFS($A$2:A11,A11,$F$2:F11,F11,$K$2:K11,"")<=SUMIFS(REFERENTIAL_CONTROL!$K:$K,REFERENTIAL_CONTROL!$H:$H,A11,REFERENTIAL_CONTROL!$I:$I,IFERROR(INDEX(Dim_Unvan!$A:$A,MATCH(F11,Dim_Unvan!$B:$B,0)),"")),"Norm Fazlası","Norma Uygun")) | I11: ALİ KALIN | N11: =IFERROR(VLOOKUP(M11,Dim_CikisNedeni!$A:$B,2,FALSE()),"") | O11: =IF(I11="","",IF(K11<>"","Pasif","Aktif")) | P11: =IF(J11="","",IF(K11<>"",K11-J11,TODAY()-J11)) | Q11: =IF(P11="","",ROUND(P11/365,1))
A12: M038 | B12: =IFERROR(VLOOKUP(A12,Dim_Magaza!$A:$C,2,FALSE()),"") | C12: =IFERROR(VLOOKUP(A12,Dim_Magaza!$A:$C,3,FALSE()),"") | D12: U051 | E12: =IFERROR(VLOOKUP(D12,Dim_Unvan!$A:$B,2,FALSE()),"") | F12: MANAV | G12: =IF(OR(A12="",F12="",I12="",K12<>""),"",IF(COUNTIFS($A$2:A12,A12,$F$2:F12,F12,$K$2:K12,"")<=SUMIFS(REFERENTIAL_CONTROL!$K:$K,REFERENTIAL_CONTROL!$H:$H,A12,REFERENTIAL_CONTROL!$I:$I,IFERROR(INDEX(Dim_Unvan!$A:$A,MATCH(F12,Dim_Unvan!$B:$B,0)),"")),"Norm Fazlası","Norma Uygun")) | I12: ABDÜLHAMİT ÖZDEMİR | N12: =IFERROR(VLOOKUP(M12,Dim_CikisNedeni!$A:$B,2,FALSE()),"") | O12: =IF(I12="","",IF(K12<>"","Pasif","Aktif")) | P12: =IF(J12="","",IF(K12<>"",K12-J12,TODAY()-J12)) | Q12: =IF(P12="","",ROUND(P12/365,1))
A13: M039 | B13: =IFERROR(VLOOKUP(A13,Dim_Magaza!$A:$C,2,FALSE()),"") | C13: =IFERROR(VLOOKUP(A13,Dim_Magaza!$A:$C,3,FALSE()),"") | D13: U052 | E13: =IFERROR(VLOOKUP(D13,Dim_Unvan!$A:$B,2,FALSE()),"") | F13: YÖNETİCİ | G13: =IF(OR(A13="",F13="",I13="",K13<>""),"",IF(COUNTIFS($A$2:A13,A13,$F$2:F13,F13,$K$2:K13,"")<=SUMIFS(REFERENTIAL_CONTROL!$K:$K,REFERENTIAL_CONTROL!$H:$H,A13,REFERENTIAL_CONTROL!$I:$I,IFERROR(INDEX(Dim_Unvan!$A:$A,MATCH(F13,Dim_Unvan!$B:$B,0)),"")),"Norm Fazlası","Norma Uygun")) | I13: HANDE DURUKAN | N13: =IFERROR(VLOOKUP(M13,Dim_CikisNedeni!$A:$B,2,FALSE()),"") | O13: =IF(I13="","",IF(K13<>"","Pasif","Aktif")) | P13: =IF(J13="","",IF(K13<>"",K13-J13,TODAY()-J13)) | Q13: =IF(P13="","",ROUND(P13/365,1))
A14: M039 | B14: =IFERROR(VLOOKUP(A14,Dim_Magaza!$A:$C,2,FALSE()),"") | C14: =IFERROR(VLOOKUP(A14,Dim_Magaza!$A:$C,3,FALSE()),"") | D14: U038 | E14: =IFERROR(VLOOKUP(D14,Dim_Unvan!$A:$B,2,FALSE()),"") | F14: YÖNETİCİ YARDIMCISI | G14: =IF(OR(A14="",F14="",I14="",K14<>""),"",IF(COUNTIFS($A$2:A14,A14,$F$2:F14,F14,$K$2:K14,"")<=SUMIFS(REFERENTIAL_CONTROL!$K:$K,REFERENTIAL_CONTROL!$H:$H,A14,REFERENTIAL_CONTROL!$I:$I,IFERROR(INDEX(Dim_Unvan!$A:$A,MATCH(F14,Dim_Unvan!$B:$B,0)),"")),"Norm Fazlası","Norma Uygun")) | I14: HEDİYE ASLAN | N14: =IFERROR(VLOOKUP(M14,Dim_CikisNedeni!$A:$B,2,FALSE()),"") | O14: =IF(I14="","",IF(K14<>"","Pasif","Aktif")) | P14: =IF(J14="","",IF(K14<>"",K14-J14,TODAY()-J14)) | Q14: =IF(P14="","",ROUND(P14/365,1))
... A597: M037 | B597: =IFERROR(VLOOKUP(A597,Dim_Magaza!$A:$C,2,FALSE()),"") | C597: =IFERROR(VLOOKUP(A597,Dim_Magaza!$A:$C,3,FALSE()),"") | D597: U034 | E597: =IFERROR(VLOOKUP(D597,Dim_Unvan!$A:$B,2,FALSE()),"") | F597: UNLU MAMÜLLER | G597: =IF(OR(A597="",F597="",I597="",K597<>""),"",IF(COUNTIFS($A$2:A597,A597,$F$2:F597,F597,$K$2:K597,"")<=SUMIFS(REFERENTIAL_CONTROL!$K:$K,REFERENTIAL_CONTROL!$H:$H,A597,REFERENTIAL_CONTROL!$I:$I,IFERROR(INDEX(Dim_Unvan!$A:$A,MATCH(F597,Dim_Unvan!$B:$B,0)),"")),"Norm Fazlası","Norma Uygun")) | I597: MİKAİL DOĞMUŞ | N597: =IFERROR(VLOOKUP(M597,Dim_CikisNedeni!$A:$B,2,FALSE()),"") | O597: =IF(I597="","",IF(K597<>"","Pasif","Aktif")) | P597: =IF(J597="","",IF(K597<>"",K597-J597,TODAY()-J597)) | Q597: =IF(P597="","",ROUND(P597/365,1))
B598: =IFERROR(VLOOKUP(A598,Dim_Magaza!$A:$C,2,FALSE()),"") | C598: =IFERROR(VLOOKUP(A598,Dim_Magaza!$A:$C,3,FALSE()),"") | E598: =IFERROR(VLOOKUP(D598,Dim_Unvan!$A:$B,2,FALSE()),"") | G598: =IF(OR(A598="",F598="",I598="",K598<>""),"",IF(COUNTIFS($A$2:A598,A598,$F$2:F598,F598,$K$2:K598,"")<=SUMIFS(REFERENTIAL_CONTROL!$K:$K,REFERENTIAL_CONTROL!$H:$H,A598,REFERENTIAL_CONTROL!$I:$I,IFERROR(INDEX(Dim_Unvan!$A:$A,MATCH(F598,Dim_Unvan!$B:$B,0)),"")),"Norm Fazlası","Norma Uygun")) | N598: =IFERROR(VLOOKUP(M598,Dim_CikisNedeni!$A:$B,2,FALSE()),"") | O598: =IF(I598="","",IF(K598<>"","Pasif","Aktif")) | P598: =IF(J598="","",IF(K598<>"",K598-J598,TODAY()-J598)) | Q598: =IF(P598="","",ROUND(P598/365,1))
B599: =IFERROR(VLOOKUP(A599,Dim_Magaza!$A:$C,2,FALSE()),"") | C599: =IFERROR(VLOOKUP(A599,Dim_Magaza!$A:$C,3,FALSE()),"") | E599: =IFERROR(VLOOKUP(D599,Dim_Unvan!$A:$B,2,FALSE()),"") | G599: =IF(OR(A599="",F599="",I599="",K599<>""),"",IF(COUNTIFS($A$2:A599,A599,$F$2:F599,F599,$K$2:K599,"")<=SUMIFS(REFERENTIAL_CONTROL!$K:$K,REFERENTIAL_CONTROL!$H:$H,A599,REFERENTIAL_CONTROL!$I:$I,IFERROR(INDEX(Dim_Unvan!$A:$A,MATCH(F599,Dim_Unvan!$B:$B,0)),"")),"Norm Fazlası","Norma Uygun")) | N599: =IFERROR(VLOOKUP(M599,Dim_CikisNedeni!$A:$B,2,FALSE()),"") | O599: =IF(I599="","",IF(K599<>"","Pasif","Aktif")) | P599: =IF(J599="","",IF(K599<>"",K599-J599,TODAY()-J599)) | Q599: =IF(P599="","",ROUND(P599/365,1))
B600: =IFERROR(VLOOKUP(A600,Dim_Magaza!$A:$C,2,FALSE()),"") | C600: =IFERROR(VLOOKUP(A600,Dim_Magaza!$A:$C,3,FALSE()),"") | E600: =IFERROR(VLOOKUP(D600,Dim_Unvan!$A:$B,2,FALSE()),"") | G600: =IF(OR(A600="",F600="",I600="",K600<>""),"",IF(COUNTIFS($A$2:A600,A600,$F$2:F600,F600,$K$2:K600,"")<=SUMIFS(REFERENTIAL_CONTROL!$K:$K,REFERENTIAL_CONTROL!$H:$H,A600,REFERENTIAL_CONTROL!$I:$I,IFERROR(INDEX(Dim_Unvan!$A:$A,MATCH(F600,Dim_Unvan!$B:$B,0)),"")),"Norm Fazlası","Norma Uygun")) | N600: =IFERROR(VLOOKUP(M600,Dim_CikisNedeni!$A:$B,2,FALSE()),"") | O600: =IF(I600="","",IF(K600<>"","Pasif","Aktif")) | P600: =IF(J600="","",IF(K600<>"",K600-J600,TODAY()-J600)) | Q600: =IF(P600="","",ROUND(P600/365,1))
B601: =IFERROR(VLOOKUP(A601,Dim_Magaza!$A:$C,2,FALSE()),"") | C601: =IFERROR(VLOOKUP(A601,Dim_Magaza!$A:$C,3,FALSE()),"") | E601: =IFERROR(VLOOKUP(D601,Dim_Unvan!$A:$B,2,FALSE()),"") | G601: =IF(OR(A601="",F601="",I601="",K601<>""),"",IF(COUNTIFS($A$2:A601,A601,$F$2:F601,F601,$K$2:K601,"")<=SUMIFS(REFERENTIAL_CONTROL!$K:$K,REFERENTIAL_CONTROL!$H:$H,A601,REFERENTIAL_CONTROL!$I:$I,IFERROR(INDEX(Dim_Unvan!$A:$A,MATCH(F601,Dim_Unvan!$B:$B,0)),"")),"Norm Fazlası","Norma Uygun")) | N601: =IFERROR(VLOOKUP(M601,Dim_CikisNedeni!$A:$B,2,FALSE()),"") | O601: =IF(I601="","",IF(K601<>"","Pasif","Aktif")) | P601: =IF(J601="","",IF(K601<>"",K601-J601,TODAY()-J601)) | Q601: =IF(P601="","",ROUND(P601/365,1))
B602: =IFERROR(VLOOKUP(A602,Dim_Magaza!$A:$C,2,FALSE()),"") | C602: =IFERROR(VLOOKUP(A602,Dim_Magaza!$A:$C,3,FALSE()),"") | E602: =IFERROR(VLOOKUP(D602,Dim_Unvan!$A:$B,2,FALSE()),"") | G602: =IF(OR(A602="",F602="",I602="",K602<>""),"",IF(COUNTIFS($A$2:A602,A602,$F$2:F602,F602,$K$2:K602,"")<=SUMIFS(REFERENTIAL_CONTROL!$K:$K,REFERENTIAL_CONTROL!$H:$H,A602,REFERENTIAL_CONTROL!$I:$I,IFERROR(INDEX(Dim_Unvan!$A:$A,MATCH(F602,Dim_Unvan!$B:$B,0)),"")),"Norm Fazlası","Norma Uygun")) | N602: =IFERROR(VLOOKUP(M602,Dim_CikisNedeni!$A:$B,2,FALSE()),"") | O602: =IF(I602="","",IF(K602<>"","Pasif","Aktif")) | P602: =IF(J602="","",IF(K602<>"",K602-J602,TODAY()-J602)) | Q602: =IF(P602="","",ROUND(P602/365,1))
B603: =IFERROR(VLOOKUP(A603,Dim_Magaza!$A:$C,2,FALSE()),"") | C603: =IFERROR(VLOOKUP(A603,Dim_Magaza!$A:$C,3,FALSE()),"") | E603: =IFERROR(VLOOKUP(D603,Dim_Unvan!$A:$B,2,FALSE()),"") | G603: =IF(OR(A603="",F603="",I603="",K603<>""),"",IF(COUNTIFS($A$2:A603,A603,$F$2:F603,F603,$K$2:K603,"")<=SUMIFS(REFERENTIAL_CONTROL!$K:$K,REFERENTIAL_CONTROL!$H:$H,A603,REFERENTIAL_CONTROL!$I:$I,IFERROR(INDEX(Dim_Unvan!$A:$A,MATCH(F603,Dim_Unvan!$B:$B,0)),"")),"Norm Fazlası","Norma Uygun")) | N603: =IFERROR(VLOOKUP(M603,Dim_CikisNedeni!$A:$B,2,FALSE()),"") | O603: =IF(I603="","",IF(K603<>"","Pasif","Aktif")) | P603: =IF(J603="","",IF(K603<>"",K603-J603,TODAY()-J603)) | Q603: =IF(P603="","",ROUND(P603/365,1))
B604: =IFERROR(VLOOKUP(A604,Dim_Magaza!$A:$C,2,FALSE()),"") | C604: =IFERROR(VLOOKUP(A604,Dim_Magaza!$A:$C,3,FALSE()),"") | E604: =IFERROR(VLOOKUP(D604,Dim_Unvan!$A:$B,2,FALSE()),"") | G604: =IF(OR(A604="",F604="",I604="",K604<>""),"",IF(COUNTIFS($A$2:A604,A604,$F$2:F604,F604,$K$2:K604,"")<=SUMIFS(REFERENTIAL_CONTROL!$K:$K,REFERENTIAL_CONTROL!$H:$H,A604,REFERENTIAL_CONTROL!$I:$I,IFERROR(INDEX(Dim_Unvan!$A:$A,MATCH(F604,Dim_Unvan!$B:$B,0)),"")),"Norm Fazlası","Norma Uygun")) | N604: =IFERROR(VLOOKUP(M604,Dim_CikisNedeni!$A:$B,2,FALSE()),"") | O604: =IF(I604="","",IF(K604<>"","Pasif","Aktif")) | P604: =IF(J604="","",IF(K604<>"",K604-J604,TODAY()-J604)) | Q604: =IF(P604="","",ROUND(P604/365,1))
B605: =IFERROR(VLOOKUP(A605,Dim_Magaza!$A:$C,2,FALSE()),"") | C605: =IFERROR(VLOOKUP(A605,Dim_Magaza!$A:$C,3,FALSE()),"") | E605: =IFERROR(VLOOKUP(D605,Dim_Unvan!$A:$B,2,FALSE()),"") | G605: =IF(OR(A605="",F605="",I605="",K605<>""),"",IF(COUNTIFS($A$2:A605,A605,$F$2:F605,F605,$K$2:K605,"")<=SUMIFS(REFERENTIAL_CONTROL!$K:$K,REFERENTIAL_CONTROL!$H:$H,A605,REFERENTIAL_CONTROL!$I:$I,IFERROR(INDEX(Dim_Unvan!$A:$A,MATCH(F605,Dim_Unvan!$B:$B,0)),"")),"Norm Fazlası","Norma Uygun")) | N605: =IFERROR(VLOOKUP(M605,Dim_CikisNedeni!$A:$B,2,FALSE()),"") | O605: =IF(I605="","",IF(K605<>"","Pasif","Aktif")) | P605: =IF(J605="","",IF(K605<>"",K605-J605,TODAY()-J605)) | Q605: =IF(P605="","",ROUND(P605/365,1))
B606: =IFERROR(VLOOKUP(A606,Dim_Magaza!$A:$C,2,FALSE()),"") | C606: =IFERROR(VLOOKUP(A606,Dim_Magaza!$A:$C,3,FALSE()),"") | E606: =IFERROR(VLOOKUP(D606,Dim_Unvan!$A:$B,2,FALSE()),"") | G606: =IF(OR(A606="",F606="",I606="",K606<>""),"",IF(COUNTIFS($A$2:A606,A606,$F$2:F606,F606,$K$2:K606,"")<=SUMIFS(REFERENTIAL_CONTROL!$K:$K,REFERENTIAL_CONTROL!$H:$H,A606,REFERENTIAL_CONTROL!$I:$I,IFERROR(INDEX(Dim_Unvan!$A:$A,MATCH(F606,Dim_Unvan!$B:$B,0)),"")),"Norm Fazlası","Norma Uygun")) | N606: =IFERROR(VLOOKUP(M606,Dim_CikisNedeni!$A:$B,2,FALSE()),"") | O606: =IF(I606="","",IF(K606<>"","Pasif","Aktif")) | P606: =IF(J606="","",IF(K606<>"",K606-J606,TODAY()-J606)) | Q606: =IF(P606="","",ROUND(P606/365,1))
B607: =IFERROR(VLOOKUP(A607,Dim_Magaza!$A:$C,2,FALSE()),"") | C607: =IFERROR(VLOOKUP(A607,Dim_Magaza!$A:$C,3,FALSE()),"") | E607: =IFERROR(VLOOKUP(D607,Dim_Unvan!$A:$B,2,FALSE()),"") | G607: =IF(OR(A607="",F607="",I607="",K607<>""),"",IF(COUNTIFS($A$2:A607,A607,$F$2:F607,F607,$K$2:K607,"")<=SUMIFS(REFERENTIAL_CONTROL!$K:$K,REFERENTIAL_CONTROL!$H:$H,A607,REFERENTIAL_CONTROL!$I:$I,IFERROR(INDEX(Dim_Unvan!$A:$A,MATCH(F607,Dim_Unvan!$B:$B,0)),"")),"Norm Fazlası","Norma Uygun")) | N607: =IFERROR(VLOOKUP(M607,Dim_CikisNedeni!$A:$B,2,FALSE()),"") | O607: =IF(I607="","",IF(K607<>"","Pasif","Aktif")) | P607: =IF(J607="","",IF(K607<>"",K607-J607,TODAY()-J607)) | Q607: =IF(P607="","",ROUND(P607/365,1))
B608: =IFERROR(VLOOKUP(A608,Dim_Magaza!$A:$C,2,FALSE()),"") | C608: =IFERROR(VLOOKUP(A608,Dim_Magaza!$A:$C,3,FALSE()),"") | E608: =IFERROR(VLOOKUP(D608,Dim_Unvan!$A:$B,2,FALSE()),"") | G608: =IF(OR(A608="",F608="",I608="",K608<>""),"",IF(COUNTIFS($A$2:A608,A608,$F$2:F608,F608,$K$2:K608,"")<=SUMIFS(REFERENTIAL_CONTROL!$K:$K,REFERENTIAL_CONTROL!$H:$H,A608,REFERENTIAL_CONTROL!$I:$I,IFERROR(INDEX(Dim_Unvan!$A:$A,MATCH(F608,Dim_Unvan!$B:$B,0)),"")),"Norm Fazlası","Norma Uygun")) | N608: =IFERROR(VLOOKUP(M608,Dim_CikisNedeni!$A:$B,2,FALSE()),"") | O608: =IF(I608="","",IF(K608<>"","Pasif","Aktif")) | P608: =IF(J608="","",IF(K608<>"",K608-J608,TODAY()-J608)) | Q608: =IF(P608="","",ROUND(P608/365,1))
B609: =IFERROR(VLOOKUP(A609,Dim_Magaza!$A:$C,2,FALSE()),"") | C609: =IFERROR(VLOOKUP(A609,Dim_Magaza!$A:$C,3,FALSE()),"") | E609: =IFERROR(VLOOKUP(D609,Dim_Unvan!$A:$B,2,FALSE()),"") | G609: =IF(OR(A609="",F609="",I609="",K609<>""),"",IF(COUNTIFS($A$2:A609,A609,$F$2:F609,F609,$K$2:K609,"")<=SUMIFS(REFERENTIAL_CONTROL!$K:$K,REFERENTIAL_CONTROL!$H:$H,A609,REFERENTIAL_CONTROL!$I:$I,IFERROR(INDEX(Dim_Unvan!$A:$A,MATCH(F609,Dim_Unvan!$B:$B,0)),"")),"Norm Fazlası","Norma Uygun")) | N609: =IFERROR(VLOOKUP(M609,Dim_CikisNedeni!$A:$B,2,FALSE()),"") | O609: =IF(I609="","",IF(K609<>"","Pasif","Aktif")) | P609: =IF(J609="","",IF(K609<>"",K609-J609,TODAY()-J609)) | Q609: =IF(P609="","",ROUND(P609/365,1))
... B738: =IFERROR(VLOOKUP(A738,Dim_Magaza!$A:$C,2,FALSE()),"") | C738: =IFERROR(VLOOKUP(A738,Dim_Magaza!$A:$C,3,FALSE()),"") | E738: =IFERROR(VLOOKUP(D738,Dim_Unvan!$A:$B,2,FALSE()),"") | G738: =IF(OR(A738="",F738="",I738="",K738<>""),"",IF(COUNTIFS($A$2:A738,A738,$F$2:F738,F738,$K$2:K738,"")<=SUMIFS(REFERENTIAL_CONTROL!$K:$K,REFERENTIAL_CONTROL!$H:$H,A738,REFERENTIAL_CONTROL!$I:$I,IFERROR(INDEX(Dim_Unvan!$A:$A,MATCH(F738,Dim_Unvan!$B:$B,0)),"")),"Norm Fazlası","Norma Uygun")) | N738: =IFERROR(VLOOKUP(M738,Dim_CikisNedeni!$A:$B,2,FALSE()),"") | O738: =IF(I738="","",IF(K738<>"","Pasif","Aktif")) | P738: =IF(J738="","",IF(K738<>"",K738-J738,TODAY()-J738)) | Q738: =IF(P738="","",ROUND(P738/365,1))

Sheet Dim_Unvan
A1: UnvanID | B1: Unvan
A2: U001 | B2: ARAÇ FİLO SORUMLUSU
A3: U002 | B3: BAKLİYAT
A4: U003 | B4: BEKÇİ
A5: U004 | B5: BÖLGE MÜDÜRÜ
A6: U005 | B6: BİLGİ İŞLEM
A7: U006 | B7: DANIŞMA
A8: U007 | B8: DESTEK PERSONELİ
A9: U008 | B9: DEPO MÜDÜRÜ
A10: U009 | B10: FİNANS
A11: U010 | B11: GENEL MUHASEBE
A12: U011 | B12: GENEL MÜDÜR YARDIMCISI
... A61: U060 | B61: ANAHTARCI

Sheet Dim_Magaza
A1: MağazaID | B1: Mağaza | C1: Bölge Sorumlusu
A2: M001 | B2: AKEVLER | C2: ERTAN TEKİ
A3: M002 | B3: AYDIN EFELER | C3: CÜNEYT ÇIKRIKÇI - AYŞE AVCU
A4: M003 | B4: AYDIN EFELER-2 | C4: CÜNEYT ÇIKRIKÇI - AYŞE AVCU
A5: M004 | B5: AYDIN FATİH | C5: CÜNEYT ÇIKRIKÇI - AYŞE AVCU
A6: M005 | B6: AYDIN FATİH-2 | C6: CÜNEYT ÇIKRIKÇI - AYŞE AVCU
A7: M006 | B7: AYDIN GİRNE | C7: CÜNEYT ÇIKRIKÇI - AYŞE AVCU
A8: M007 | B8: AYDIN MİMARSİNAN | C8: CÜNEYT ÇIKRIKÇI - AYŞE AVCU
A9: M008 | B9: AYRANCILAR | C9: CÜNEYT ÇIKRIKÇI - AYŞE AVCU
A10: M009 | B10: BALÇOVA | C10: ERTAN TEKİ
A11: M010 | B11: BAYRAKLI | C11: DERYA YARDIMCI
A12: M011 | B12: BOZYAKA | C12: ERTAN TEKİ
... A54: M057 | B54: BUCA2 | C54: ERTAN TEKİ

Sheet Dim_Tarih
A1: Tarih | B1: Yıl | C1: Ay No | D1: Ay Adı | E1: Çeyrek | F1: Hafta No | G1: Hafta Günü No | H1: Hafta Günü Adı
A2: 42005 | B2: =IF(A2="","",YEAR(A2)) | C2: =IF(A2="","",MONTH(A2)) | D2: =IF(A2="","",CHOOSE(MONTH(A2),"Ocak","Şubat","Mart","Nisan","Mayıs","Haziran","Temmuz","Ağustos","Eylül","Ekim","Kasım","Aralık")) | E2: =IF(A2="","",ROUNDUP(MONTH(A2)/3,0)) | F2: =IF(A2="","",WEEKNUM(A2,2)) | G2: =IF(A2="","",WEEKDAY(A2,2)) | H2: =IF(A2="","",CHOOSE(WEEKDAY(A2,2),"Pazartesi","Salı","Çarşamba","Perşembe","Cuma","Cumartesi","Pazar"))
A3: 42006 | B3: =IF(A3="","",YEAR(A3)) | C3: =IF(A3="","",MONTH(A3)) | D3: =IF(A3="","",CHOOSE(MONTH(A3),"Ocak","Şubat","Mart","Nisan","Mayıs","Haziran","Temmuz","Ağustos","Eylül","Ekim","Kasım","Aralık")) | E3: =IF(A3="","",ROUNDUP(MONTH(A3)/3,0)) | F3: =IF(A3="","",WEEKNUM(A3,2)) | G3: =IF(A3="","",WEEKDAY(A3,2)) | H3: =IF(A3="","",CHOOSE(WEEKDAY(A3,2),"Pazartesi","Salı","Çarşamba","Perşembe","Cuma","Cumartesi","Pazar"))
A4: 42007 | B4: =IF(A4="","",YEAR(A4)) | C4: =IF(A4="","",MONTH(A4)) | D4: =IF(A4="","",CHOOSE(MONTH(A4),"Ocak","Şubat","Mart","Nisan","Mayıs","Haziran","Temmuz","Ağustos","Eylül","Ekim","Kasım","Aralık")) | E4: =IF(A4="","",ROUNDUP(MONTH(A4)/3,0)) | F4: =IF(A4="","",WEEKNUM(A4,2)) | G4: =IF(A4="","",WEEKDAY(A4,2)) | H4: =IF(A4="","",CHOOSE(WEEKDAY(A4,2),"Pazartesi","Salı","Çarşamba","Perşembe","Cuma","Cumartesi","Pazar"))
A5: 42008 | B5: =IF(A5="","",YEAR(A5)) | C5: =IF(A5="","",MONTH(A5)) | D5: =IF(A5="","",CHOOSE(MONTH(A5),"Ocak","Şubat","Mart","Nisan","Mayıs","Haziran","Temmuz","Ağustos","Eylül","Ekim","Kasım","Aralık")) | E5: =IF(A5="","",ROUNDUP(MONTH(A5)/3,0)) | F5: =IF(A5="","",WEEKNUM(A5,2)) | G5: =IF(A5="","",WEEKDAY(A5,2)) | H5: =IF(A5="","",CHOOSE(WEEKDAY(A5,2),"Pazartesi","Salı","Çarşamba","Perşembe","Cuma","Cumartesi","Pazar"))
A6: 42009 | B6: =IF(A6="","",YEAR(A6)) | C6: =IF(A6="","",MONTH(A6)) | D6: =IF(A6="","",CHOOSE(MONTH(A6),"Ocak","Şubat","Mart","Nisan","Mayıs","Haziran","Temmuz","Ağustos","Eylül","Ekim","Kasım","Aralık")) | E6: =IF(A6="","",ROUNDUP(MONTH(A6)/3,0)) | F6: =IF(A6="","",WEEKNUM(A6,2)) | G6: =IF(A6="","",WEEKDAY(A6,2)) | H6: =IF(A6="","",CHOOSE(WEEKDAY(A6,2),"Pazartesi","Salı","Çarşamba","Perşembe","Cuma","Cumartesi","Pazar"))
A7: 42010 | B7: =IF(A7="","",YEAR(A7)) | C7: =IF(A7="","",MONTH(A7)) | D7: =IF(A7="","",CHOOSE(MONTH(A7),"Ocak","Şubat","Mart","Nisan","Mayıs","Haziran","Temmuz","Ağustos","Eylül","Ekim","Kasım","Aralık")) | E7: =IF(A7="","",ROUNDUP(MONTH(A7)/3,0)) | F7: =IF(A7="","",WEEKNUM(A7,2)) | G7: =IF(A7="","",WEEKDAY(A7,2)) | H7: =IF(A7="","",CHOOSE(WEEKDAY(A7,2),"Pazartesi","Salı","Çarşamba","Perşembe","Cuma","Cumartesi","Pazar"))
A8: 42011 | B8: =IF(A8="","",YEAR(A8)) | C8: =IF(A8="","",MONTH(A8)) | D8: =IF(A8="","",CHOOSE(MONTH(A8),"Ocak","Şubat","Mart","Nisan","Mayıs","Haziran","Temmuz","Ağustos","Eylül","Ekim","Kasım","Aralık")) | E8: =IF(A8="","",ROUNDUP(MONTH(A8)/3,0)) | F8: =IF(A8="","",WEEKNUM(A8,2)) | G8: =IF(A8="","",WEEKDAY(A8,2)) | H8: =IF(A8="","",CHOOSE(WEEKDAY(A8,2),"Pazartesi","Salı","Çarşamba","Perşembe","Cuma","Cumartesi","Pazar"))
A9: 42012 | B9: =IF(A9="","",YEAR(A9)) | C9: =IF(A9="","",MONTH(A9)) | D9: =IF(A9="","",CHOOSE(MONTH(A9),"Ocak","Şubat","Mart","Nisan","Mayıs","Haziran","Temmuz","Ağustos","Eylül","Ekim","Kasım","Aralık")) | E9: =IF(A9="","",ROUNDUP(MONTH(A9)/3,0)) | F9: =IF(A9="","",WEEKNUM(A9,2)) | G9: =IF(A9="","",WEEKDAY(A9,2)) | H9: =IF(A9="","",CHOOSE(WEEKDAY(A9,2),"Pazartesi","Salı","Çarşamba","Perşembe","Cuma","Cumartesi","Pazar"))
A10: 42013 | B10: =IF(A10="","",YEAR(A10)) | C10: =IF(A10="","",MONTH(A10)) | D10: =IF(A10="","",CHOOSE(MONTH(A10),"Ocak","Şubat","Mart","Nisan","Mayıs","Haziran","Temmuz","Ağustos","Eylül","Ekim","Kasım","Aralık")) | E10: =IF(A10="","",ROUNDUP(MONTH(A10)/3,0)) | F10: =IF(A10="","",WEEKNUM(A10,2)) | G10: =IF(A10="","",WEEKDAY(A10,2)) | H10: =IF(A10="","",CHOOSE(WEEKDAY(A10,2),"Pazartesi","Salı","Çarşamba","Perşembe","Cuma","Cumartesi","Pazar"))
A11: 42014 | B11: =IF(A11="","",YEAR(A11)) | C11: =IF(A11="","",MONTH(A11)) | D11: =IF(A11="","",CHOOSE(MONTH(A11),"Ocak","Şubat","Mart","Nisan","Mayıs","Haziran","Temmuz","Ağustos","Eylül","Ekim","Kasım","Aralık")) | E11: =IF(A11="","",ROUNDUP(MONTH(A11)/3,0)) | F11: =IF(A11="","",WEEKNUM(A11,2)) | G11: =IF(A11="","",WEEKDAY(A11,2)) | H11: =IF(A11="","",CHOOSE(WEEKDAY(A11,2),"Pazartesi","Salı","Çarşamba","Perşembe","Cuma","Cumartesi","Pazar"))
A12: 42015 | B12: =IF(A12="","",YEAR(A12)) | C12: =IF(A12="","",MONTH(A12)) | D12: =IF(A12="","",CHOOSE(MONTH(A12),"Ocak","Şubat","Mart","Nisan","Mayıs","Haziran","Temmuz","Ağustos","Eylül","Ekim","Kasım","Aralık")) | E12: =IF(A12="","",ROUNDUP(MONTH(A12)/3,0)) | F12: =IF(A12="","",WEEKNUM(A12,2)) | G12: =IF(A12="","",WEEKDAY(A12,2)) | H12: =IF(A12="","",CHOOSE(WEEKDAY(A12,2),"Pazartesi","Salı","Çarşamba","Perşembe","Cuma","Cumartesi","Pazar"))
A13: 42016 | B13: =IF(A13="","",YEAR(A13)) | C13: =IF(A13="","",MONTH(A13)) | D13: =IF(A13="","",CHOOSE(MONTH(A13),"Ocak","Şubat","Mart","Nisan","Mayıs","Haziran","Temmuz","Ağustos","Eylül","Ekim","Kasım","Aralık")) | E13: =IF(A13="","",ROUNDUP(MONTH(A13)/3,0)) | F13: =IF(A13="","",WEEKNUM(A13,2)) | G13: =IF(A13="","",WEEKDAY(A13,2)) | H13: =IF(A13="","",CHOOSE(WEEKDAY(A13,2),"Pazartesi","Salı","Çarşamba","Perşembe","Cuma","Cumartesi","Pazar"))
... A5845: 47848 | B5845: =IF(A5845="","",YEAR(A5845)) | C5845: =IF(A5845="","",MONTH(A5845)) | D5845: =IF(A5845="","",CHOOSE(MONTH(A5845),"Ocak","Şubat","Mart","Nisan","Mayıs","Haziran","Temmuz","Ağustos","Eylül","Ekim","Kasım","Aralık")) | E5845: =IF(A5845="","",ROUNDUP(MONTH(A5845)/3,0)) | F5845: =IF(A5845="","",WEEKNUM(A5845,2)) | G5845: =IF(A5845="","",WEEKDAY(A5845,2)) | H5845: =IF(A5845="","",CHOOSE(WEEKDAY(A5845,2),"Pazartesi","Salı","Çarşamba","Perşembe","Cuma","Cumartesi","Pazar"))

Sheet Çarpanlar
A1: NORM KADRO ÇARPANLARI
A2: Kriter | B2: Ağırlık | C2: Ne İçin Kullanılır | D2: Normalizasyon
A3: Fiş Adedi | B3: 0.35 | C3: Müşteri trafiği ve kasa işlem yükü | D3: Günlük fiş / en yüksek günlük fiş
A4: Ciro | B4: 0.2 | C4: Ticari hacim ve reyon hareketliliği | D4: Günlük ciro / en yüksek günlük ciro
A5: Satış Alanı m² | B5: 0.15 | C5: Raf, temizlik, reyon ve saha yayılımı | D5: m² / en yüksek m²
A6: Kasa Sayısı | B6: 0.1 | C6: Açık kasa ve vardiya ihtiyacı | D6: Kasa / en yüksek kasa
A7: Departman Sayısı | B7: 0.1 | C7: Kasap, şarküteri, unlu, manav gibi servis yükleri | D7: Departman / en yüksek departman
A8: Mal Kabul | B8: 0.05 | C8: Günlük ürün kabul ve yerleştirme yükü | D8: Mal kabul / en yüksek mal kabul
A9: İK Risk | B9: 0.05 | C9: Devamsızlık, çıkış, mesai ve bağlılık riski | D9: Risk skoru / 100
A10: Toplam | B10: 1 | C10: Ağırlık kontrolü | D10: 1 olmalı

Sheet Girdiler
A1: SENARYO GİRDİLERİ
A2: Parametre | B2: Değer | C2: Açıklama
A3: Ciro Artış % | B3: 0.1 | C3: Ciro %10 artarsa norm etkisini ölçmek için
A4: Fiş Artış % | B4: 0.12 | C4: Müşteri trafiği artış senaryosu
A5: Online Artış % | B5: 0.2 | C5: Sanal market büyümesi
A6: Devamsızlık Risk Payı | B6: 0.05 | C6: Fiili iş gücü kaybı payı
A7: İzin/Yedek Kadro Payı | B7: 0.08 | C7: Yıllık izin ve haftalık izin payı
A8: Yoğun Sezon Katsayısı | B8: 1.1 | C8: Bayram/yaz/kampanya dönemi katsayısı
A9: Verimlilik İyileşme % | B9: -0.05 | C9: Süreç iyileştirmeyle norm azaltma etkisi

Sheet Mağaza Özellikleri
A1: MAĞAZA OPERASYONEL ÖZELLİKLERİ
A2: MagazaID | B2: Mağaza | C2: Bölge | D2: Tip | E2: Satış Alanı m² | F2: Depo Alanı m² | G2: Kasa Sayısı | H2: Kasap | I2: Şarküteri | J2: Unlu Mamuller | K2: Manav | L2: Günlük Açık Saat | M2: Departman Sayısı
A3: M001 | B3: AKEVLER | C3: ERTAN TEKİ | D3: Mağaza | E3: 1224 | F3: 48 | G3: 8 | H3: Var | I3: Yok | J3: Var | K3: Var | L3: 16 | M3: 3
A4: M002 | B4: AYDIN EFELER | C4: CÜNEYT ÇIKRIKÇI - AYŞE AVCU | D4: Mağaza | E4: 322 | F4: 102 | G4: 7 | H4: Var | I4: Var | J4: Var | K4: Var | L4: 14 | M4: 4
A5: M003 | B5: AYDIN EFELER-2 | C5: CÜNEYT ÇIKRIKÇI - AYŞE AVCU | D5: Mağaza | E5: 1207 | F5: 241 | G5: 12 | H5: Yok | I5: Var | J5: Yok | K5: Yok | L5: 16 | M5: 1
A6: M004 | B6: AYDIN FATİH | C6: CÜNEYT ÇIKRIKÇI - AYŞE AVCU | D6: Mağaza | E6: 649 | F6: 58 | G6: 4 | H6: Yok | I6: Yok | J6: Yok | K6: Var | L6: 16 | M6: 1
A7: M005 | B7: AYDIN FATİH-2 | C7: CÜNEYT ÇIKRIKÇI - AYŞE AVCU | D7: Mağaza | E7: 513 | F7: 252 | G7: 9 | H7: Var | I7: Var | J7: Var | K7: Var | L7: 15 | M7: 4
A8: M006 | B8: AYDIN GİRNE | C8: CÜNEYT ÇIKRIKÇI - AYŞE AVCU | D8: Mağaza | E8: 652 | F8: 94 | G8: 4 | H8: Var | I8: Var | J8: Var | K8: Var | L8: 14 | M8: 4
A9: M007 | B9: AYDIN MİMARSİNAN | C9: CÜNEYT ÇIKRIKÇI - AYŞE AVCU | D9: Mağaza | E9: 1125 | F9: 123 | G9: 4 | H9: Var | I9: Var | J9: Yok | K9: Var | L9: 15 | M9: 3
A10: M008 | B10: AYRANCILAR | C10: CÜNEYT ÇIKRIKÇI - AYŞE AVCU | D10: Mağaza | E10: 1511 | F10: 57 | G10: 8 | H10: Var | I10: Var | J10: Var | K10: Var | L10: 14 | M10: 4
A11: M009 | B11: BALÇOVA | C11: ERTAN TEKİ | D11: Mağaza | E11: 1431 | F11: 249 | G11: 4 | H11: Var | I11: Var | J11: Yok | K11: Yok | L11: 15 | M11: 2
A12: M010 | B12: BAYRAKLI | C12: DERYA YARDIMCI | D12: Mağaza | E12: 668 | F12: 166 | G12: 8 | H12: Var | I12: Var | J12: Yok | K12: Yok | L12: 15 | M12: 2
A13: M011 | B13: BOZYAKA | C13: ERTAN TEKİ | D13: Mağaza | E13: 858 | F13: 234 | G13: 12 | H13: Var | I13: Var | J13: Var | K13: Yok | L13: 15 | M13: 3
A14: M012 | B14: BUCA | C14: DERYA YARDIMCI | D14: Mağaza | E14: 1653 | F14: 258 | G14: 12 | H14: Var | I14: Var | J14: Var | K14: Var | L14: 16 | M14: 4
... A55: M057 | B55: BUCA2 | C55: ERTAN TEKİ | D55: Merkez | E55: 1290 | F55: 4155 | G55: 0 | H55: Yok | I55: Yok | J55: Yok | K55: Yok | L55: 9 | M55: 0

Sheet Departman Matrisi
A1: DEPARTMAN MATRİSİ
A2: MagazaID | B2: Mağaza | C2: Departman | D2: Durum | E2: Günlük Hacim | F2: Öneri Katsayısı
A3: M001 | B3: AKEVLER | C3: Kasap | D3: Var | E3: 57 | F3: 1.4
A4: M001 | B4: AKEVLER | C4: Şarküteri | D4: Yok | E4: 0 | F4: 0
A5: M001 | B5: AKEVLER | C5: Unlu Mamuller | D5: Var | E5: 76 | F5: 1.9
A6: M001 | B6: AKEVLER | C6: Manav | D6: Var | E6: 14 | F6: 0.3
A7: M001 | B7: AKEVLER | C7: Depo/Mal Kabul | D7: Var | E7: 27 | F7: 0.7
A8: M001 | B8: AKEVLER | C8: Online | D8: Var | E8: 80 | F8: 2
A9: M002 | B9: AYDIN EFELER | C9: Kasap | D9: Var | E9: 14 | F9: 0.3
A10: M002 | B10: AYDIN EFELER | C10: Şarküteri | D10: Var | E10: 76 | F10: 1.9
A11: M002 | B11: AYDIN EFELER | C11: Unlu Mamuller | D11: Var | E11: 89 | F11: 2.2
A12: M002 | B12: AYDIN EFELER | C12: Manav | D12: Var | E12: 29 | F12: 0.7
A13: M002 | B13: AYDIN EFELER | C13: Depo/Mal Kabul | D13: Var | E13: 57 | F13: 1.4
A14: M002 | B14: AYDIN EFELER | C14: Online | D14: Var | E14: 10 | F14: 0.2
... A320: M057 | B320: BUCA2 | C320: Online | D320: Yok | E320: 0 | F320: 0

Sheet Günlük Operasyon
A1: GÜNLÜK OPERASYON
A2: Tarih | B2: MagazaID | C2: Mağaza | D2: Bölge | E2: Fiş Adedi | F2: Ciro | G2: Ortalama Sepet | H2: Müşteri Sayısı
A3: 46113 | B3: M001 | C3: AKEVLER | D3: ERTAN TEKİ | E3: 1372 | F3: 513564 | G3: 374.32 | H3: 1473
A4: 46113 | B4: M002 | C4: AYDIN EFELER | D4: CÜNEYT ÇIKRIKÇI - AYŞE AVCU | E4: 2116 | F4: 733197 | G4: 346.5 | H4: 2048
A5: 46113 | B5: M003 | C5: AYDIN EFELER-2 | D5: CÜNEYT ÇIKRIKÇI - AYŞE AVCU | E5: 1797 | F5: 650281 | G5: 361.87 | H5: 1656
A6: 46113 | B6: M004 | C6: AYDIN FATİH | D6: CÜNEYT ÇIKRIKÇI - AYŞE AVCU | E6: 1054 | F6: 363516 | G6: 344.89 | H6: 949
A7: 46113 | B7: M005 | C7: AYDIN FATİH-2 | D7: CÜNEYT ÇIKRIKÇI - AYŞE AVCU | E7: 1411 | F7: 729831 | G7: 517.24 | H7: 1392
A8: 46113 | B8: M006 | C8: AYDIN GİRNE | D8: CÜNEYT ÇIKRIKÇI - AYŞE AVCU | E8: 1185 | F8: 330882 | G8: 279.23 | H8: 1236
A9: 46113 | B9: M007 | C9: AYDIN MİMARSİNAN | D9: CÜNEYT ÇIKRIKÇI - AYŞE AVCU | E9: 3579 | F9: 868884 | G9: 242.77 | H9: 3539
A10: 46113 | B10: M008 | C10: AYRANCILAR | D10: CÜNEYT ÇIKRIKÇI - AYŞE AVCU | E10: 2849 | F10: 654184 | G10: 229.62 | H10: 2924
A11: 46113 | B11: M009 | C11: BALÇOVA | D11: ERTAN TEKİ | E11: 2726 | F11: 514929 | G11: 188.9 | H11: 2861
A12: 46113 | B12: M010 | C12: BAYRAKLI | D12: DERYA YARDIMCI | E12: 3020 | F12: 912440 | G12: 302.13 | H12: 2730
A13: 46113 | B13: M011 | C13: BOZYAKA | D13: ERTAN TEKİ | E13: 2086 | F13: 845943 | G13: 405.53 | H13: 1947
A14: 46113 | B14: M012 | C14: BUCA | D14: DERYA YARDIMCI | E14: 861 | F14: 341894 | G14: 397.09 | H14: 863
... A4772: 46202 | B4772: M057 | C4772: BUCA2 | D4772: ERTAN TEKİ | E4772: 0 | F4772: 0 | G4772: 0 | H4772: 0

Sheet Saatlik Yoğunluk
A1: SAATLİK YOĞUNLUK
A2: MagazaID | B2: Mağaza | C2: Saat | D2: Yoğunluk Skoru | E2: Önerilen Açık Kasa
A3: M001 | B3: AKEVLER | C3: 8 | D3: 55 | E3: 4.4
A4: M001 | B4: AKEVLER | C4: 9 | D4: 59 | E4: 4.7
A5: M001 | B5: AKEVLER | C5: 10 | D5: 57 | E5: 4.6
A6: M001 | B6: AKEVLER | C6: 11 | D6: 58 | E6: 4.6
A7: M001 | B7: AKEVLER | C7: 12 | D7: 91 | E7: 7.3
A8: M001 | B8: AKEVLER | C8: 13 | D8: 82 | E8: 6.6
A9: M001 | B9: AKEVLER | C9: 14 | D9: 35 | E9: 2.8
A10: M001 | B10: AKEVLER | C10: 15 | D10: 65 | E10: 5.2
A11: M001 | B11: AKEVLER | C11: 16 | D11: 35 | E11: 2.8
A12: M001 | B12: AKEVLER | C12: 17 | D12: 100 | E12: 8
A13: M001 | B13: AKEVLER | C13: 18 | D13: 73 | E13: 5.8
A14: M001 | B14: AKEVLER | C14: 19 | D14: 94 | E14: 7.5
... A797: M057 | B797: BUCA2 | C797: 22 | D797: 0 | E797: 0

Sheet Kasa Kullanımı
A1: KASA KULLANIMI
A2: MagazaID | B2: Mağaza | C2: Kasa | D2: Günlük Fiş | E2: Günlük Ciro | F2: Kullanım Oranı %
A3: M001 | B3: AKEVLER | C3: Kasa 1 | D3: 295 | E3: 134017 | F3: 83.8
A4: M001 | B4: AKEVLER | C4: Kasa 2 | D4: 144 | E4: 149779 | F4: 83
A5: M001 | B5: AKEVLER | C5: Kasa 3 | D5: 154 | E5: 150621 | F5: 61.4
A6: M001 | B6: AKEVLER | C6: Kasa 4 | D6: 200 | E6: 79816 | F6: 91.9
A7: M001 | B7: AKEVLER | C7: Kasa 5 | D7: 343 | E7: 145562 | F7: 58.9
A8: M001 | B8: AKEVLER | C8: Kasa 6 | D8: 214 | E8: 66955 | F8: 82.7
A9: M001 | B9: AKEVLER | C9: Kasa 7 | D9: 165 | E9: 88853 | F9: 48.7
A10: M001 | B10: AKEVLER | C10: Kasa 8 | D10: 226 | E10: 30555 | F10: 52.5
A11: M002 | B11: AYDIN EFELER | C11: Kasa 1 | D11: 230 | E11: 109938 | F11: 73.5
A12: M002 | B12: AYDIN EFELER | C12: Kasa 2 | D12: 217 | E12: 148262 | F12: 83.4
A13: M002 | B13: AYDIN EFELER | C13: Kasa 3 | D13: 237 | E13: 132903 | F13: 78.2
A14: M002 | B14: AYDIN EFELER | C14: Kasa 4 | D14: 255 | E14: 117276 | F14: 65.7
... A367: M052 | B367: ŞİRİNYER 2 | C367: Kasa 11 | D367: 122 | E367: 154720 | F367: 69.9

Sheet Online Sipariş
A1: ONLINE SİPARİŞ
A2: MagazaID | B2: Mağaza | C2: Günlük Sipariş | D2: Online Ciro | E2: Kurye/Toplayıcı İhtiyacı | F2: Norm Etkisi
A3: M001 | B3: AKEVLER | C3: 137 | D3: 55074 | E3: 7 | F3: 2.3
A4: M002 | B4: AYDIN EFELER | C4: 4 | D4: 1196 | E4: 2 | F4: 0.1
A5: M003 | B5: AYDIN EFELER-2 | C5: 126 | D5: 27594 | E5: 8 | F5: 2.1
A6: M004 | B6: AYDIN FATİH | C6: 45 | D6: 10575 | E6: 8 | F6: 0.8
A7: M005 | B7: AYDIN FATİH-2 | C7: 78 | D7: 26208 | E7: 7 | F7: 1.3
A8: M006 | B8: AYDIN GİRNE | C8: 79 | D8: 16985 | E8: 5 | F8: 1.3
A9: M007 | B9: AYDIN MİMARSİNAN | C9: 120 | D9: 45360 | E9: 8 | F9: 2
A10: M008 | B10: AYRANCILAR | C10: 70 | D10: 19530 | E10: 5 | F10: 1.2
A11: M009 | B11: BALÇOVA | C11: 118 | D11: 47908 | E11: 3 | F11: 2
A12: M010 | B12: BAYRAKLI | C12: 143 | D12: 29172 | E12: 4 | F12: 2.4
A13: M011 | B13: BOZYAKA | C13: 178 | D13: 47170 | E13: 2 | F13: 3
A14: M012 | B14: BUCA | C14: 20 | D14: 6640 | E14: 2 | F14: 0.3
... A55: M057 | B55: BUCA2 | C55: 0 | D55: 0 | E55: 0 | F55: 0

Sheet Parametreler
A1: Parametre | B1: Deger | C1: Aciklama
A2: aylik_isveren_maliyeti_fte | B2: 0 | C2: Bir çalışanın aylık toplam işveren maliyeti
A3: aylik_tahmini_katki_fte | B3: 0 | C3: Bir kişilik ek kapasitenin aylık tahmini katkısı
A4: yillik_ay_sayisi | B4: 12 | C4: Yıllık hesaplama ay sayısı
A5: minimum_guven_skoru | B5: 50 | C5: Güven skorunun alt sınırı
A6: maksimum_guven_skoru | B6: 98 | C6: Güven skorunun üst sınırı

Sheet Mal Kabul
A1: MAL KABUL
A2: MagazaID | B2: Mağaza | C2: Günlük Mal Kabul | D2: Koli/Palet | E2: Hata Sayısı | F2: Norm Etkisi
A3: M001 | B3: AKEVLER | C3: 17 | D3: 58 | E3: 7 | F3: 2.1
A4: M002 | B4: AYDIN EFELER | C4: 16 | D4: 330 | E4: 2 | F4: 2
A5: M003 | B5: AYDIN EFELER-2 | C5: 6 | D5: 65 | E5: 7 | F5: 0.8
A6: M004 | B6: AYDIN FATİH | C6: 17 | D6: 321 | E6: 5 | F6: 2.1
A7: M005 | B7: AYDIN FATİH-2 | C7: 13 | D7: 142 | E7: 5 | F7: 1.6
A8: M006 | B8: AYDIN GİRNE | C8: 9 | D8: 268 | E8: 7 | F8: 1.1
A9: M007 | B9: AYDIN MİMARSİNAN | C9: 16 | D9: 68 | E9: 7 | F9: 2
A10: M008 | B10: AYRANCILAR | C10: 10 | D10: 387 | E10: 4 | F10: 1.2
A11: M009 | B11: BALÇOVA | C11: 14 | D11: 319 | E11: 8 | F11: 1.8
A12: M010 | B12: BAYRAKLI | C12: 15 | D12: 87 | E12: 1 | F12: 1.9
A13: M011 | B13: BOZYAKA | C13: 5 | D13: 294 | E13: 2 | F13: 0.6
A14: M012 | B14: BUCA | C14: 16 | D14: 274 | E14: 3 | F14: 2
... A55: M057 | B55: BUCA2 | C55: 44 | D55: 258 | E55: 6 | F55: 5.5

Sheet Sevkiyat
A1: SEVKİYAT
A2: MagazaID | B2: Mağaza | C2: Günlük Sevkiyat | D2: İade Sevkiyat | E2: Acil Sevkiyat | F2: Operasyon Katsayısı
A3: M001 | B3: AKEVLER | C3: 11 | D3: 4 | E3: 1 | F3: 0.3
A4: M002 | B4: AYDIN EFELER | C4: 6 | D4: 6 | E4: 0 | F4: 1.2
A5: M003 | B5: AYDIN EFELER-2 | C5: 10 | D5: 0 | E5: 2 | F5: 1.6
A6: M004 | B6: AYDIN FATİH | C6: 3 | D6: 2 | E6: 0 | F6: 1.1
A7: M005 | B7: AYDIN FATİH-2 | C7: 8 | D7: 0 | E7: 0 | F7: 0.7
A8: M006 | B8: AYDIN GİRNE | C8: 12 | D8: 0 | E8: 3 | F8: 0.8
A9: M007 | B9: AYDIN MİMARSİNAN | C9: 11 | D9: 0 | E9: 2 | F9: 1.2
A10: M008 | B10: AYRANCILAR | C10: 12 | D10: 4 | E10: 0 | F10: 2.3
A11: M009 | B11: BALÇOVA | C11: 6 | D11: 4 | E11: 0 | F11: 2.1
A12: M010 | B12: BAYRAKLI | C12: 10 | D12: 6 | E12: 0 | F12: 0.3
A13: M011 | B13: BOZYAKA | C13: 10 | D13: 6 | E13: 1 | F13: 1.2
A14: M012 | B14: BUCA | C14: 11 | D14: 4 | E14: 3 | F14: 1
... A55: M057 | B55: BUCA2 | C55: 1 | D55: 0 | E55: 1 | F55: 2.5

Sheet Fire ve İade
A1: FİRE VE İADE
A2: MagazaID | B2: Mağaza | C2: Fire Oranı % | D2: Günlük İade İşlem | E2: İmha İşlem | F2: İş Yükü Etkisi
A3: M001 | B3: AKEVLER | C3: 3.05 | D3: 7 | E3: 15 | F3: 0.08
A4: M002 | B4: AYDIN EFELER | C4: 4.48 | D4: 17 | E4: 19 | F4: 1.16
A5: M003 | B5: AYDIN EFELER-2 | C5: 1.16 | D5: 7 | E5: 8 | F5: 0.47
A6: M004 | B6: AYDIN FATİH | C6: 2.99 | D6: 4 | E6: 17 | F6: 0.97
A7: M005 | B7: AYDIN FATİH-2 | C7: 1.33 | D7: 20 | E7: 10 | F7: 0.31
A8: M006 | B8: AYDIN GİRNE | C8: 0.62 | D8: 26 | E8: 6 | F8: 0.34
A9: M007 | B9: AYDIN MİMARSİNAN | C9: 2.7 | D9: 18 | E9: 4 | F9: 0.39
A10: M008 | B10: AYRANCILAR | C10: 1.47 | D10: 4 | E10: 6 | F10: 1.14
A11: M009 | B11: BALÇOVA | C11: 2.09 | D11: 8 | E11: 15 | F11: 0.25
A12: M010 | B12: BAYRAKLI | C12: 4.27 | D12: 23 | E12: 16 | F12: 1.14
A13: M011 | B13: BOZYAKA | C13: 2.75 | D13: 17 | E13: 14 | F13: 0.99
A14: M012 | B14: BUCA | C14: 4.44 | D14: 2 | E14: 16 | F14: 0.97
... A55: M057 | B55: BUCA2 | C55: 0.98 | D55: 18 | E55: 18 | F55: 0.65

Sheet Dim_CikisNedeni
A1: CikisNedeniID | B1: CikisNedeni | C1: CikisGrubu | D1: AnalizKategorisi
A2: 1 | B2: Yönetici ile anlaşamama | C2: İstifa | D2: Çalışan deneyimi
A3: 2 | B3: Çalışma arkadaşları ile anlaşamama | C3: İstifa | D3: Ekip uyumu
A4: 3 | B4: Ücret yetersizliği | C4: İstifa | D4: Ücret
A5: 4 | B5: Yan haklardan memnun olmama | C5: İstifa | D5: Yan haklar
A6: 5 | B6: Vardiya düzeninden memnun olmama | C6: İstifa | D6: Çalışma düzeni
A7: 6 | B7: Çalışma saatlerinin uzun olması | C7: İstifa | D7: Çalışma düzeni
A8: 7 | B8: İş yükünün fazla olması | C8: İstifa | D8: İş yükü
A9: 8 | B9: Görev dağılımı adaletsizliği | C9: İstifa | D9: Yönetim
A10: 9 | B10: Kariyer / terfi beklentisinin karşılanmaması | C10: İstifa | D10: Kariyer
A11: 10 | B11: Ulaşım problemi | C11: İstifa | D11: Lokasyon
A12: 11 | B12: Sağlık nedeni | C12: İstifa | D12: Kişisel
A13: 12 | B13: Ailevi nedenler | C13: İstifa | D13: Kişisel
... A31: 30 | B31: Diğer | C31: Diğer | D31: Diğer

Sheet Müşteri Şikayetleri
A1: MÜŞTERİ ŞİKAYETLERİ
A2: MagazaID | B2: Mağaza | C2: Şikayet Adedi | D2: Kasa Şikayeti | E2: Reyon Şikayeti | F2: Memnuniyet Skoru
A3: M001 | B3: AKEVLER | C3: 5 | D3: 2 | E3: 7 | F3: 70
A4: M002 | B4: AYDIN EFELER | C4: 2 | D4: 8 | E4: 1 | F4: 72
A5: M003 | B5: AYDIN EFELER-2 | C5: 0 | D5: 5 | E5: 1 | F5: 80
A6: M004 | B6: AYDIN FATİH | C6: 11 | D6: 7 | E6: 0 | F6: 90
A7: M005 | B7: AYDIN FATİH-2 | C7: 3 | D7: 4 | E7: 2 | F7: 98
A8: M006 | B8: AYDIN GİRNE | C8: 10 | D8: 3 | E8: 6 | F8: 83
A9: M007 | B9: AYDIN MİMARSİNAN | C9: 10 | D9: 5 | E9: 1 | F9: 79
A10: M008 | B10: AYRANCILAR | C10: 8 | D10: 7 | E10: 5 | F10: 73
A11: M009 | B11: BALÇOVA | C11: 12 | D11: 10 | E11: 7 | F11: 75
A12: M010 | B12: BAYRAKLI | C12: 3 | D12: 0 | E12: 7 | F12: 74
A13: M011 | B13: BOZYAKA | C13: 4 | D13: 8 | E13: 4 | F13: 83
A14: M012 | B14: BUCA | C14: 16 | D14: 9 | E14: 3 | F14: 85
... A55: M057 | B55: BUCA2 | C55: 17 | D55: 9 | E55: 7 | F55: 86

Sheet Fazla Mesai
A1: FAZLA MESAİ
A2: Ay | B2: MagazaID | C2: Mağaza | D2: Fazla Mesai Saat | E2: Fazla Mesai Maliyet | F2: Yoğunluk Seviyesi
A3: 2026-01 | B3: M001 | C3: AKEVLER | D3: 130 | E3: 30810 | F3: Düşük
A4: 2026-02 | B4: M001 | C4: AKEVLER | D4: 78 | E4: 17394 | F4: Orta
A5: 2026-03 | B5: M001 | C5: AKEVLER | D5: 168 | E5: 29736 | F5: Düşük
A6: 2026-04 | B6: M001 | C6: AKEVLER | D6: 18 | E6: 3798 | F6: Yüksek
A7: 2026-05 | B7: M001 | C7: AKEVLER | D7: 103 | E7: 23793 | F7: Yüksek
A8: 2026-06 | B8: M001 | C8: AKEVLER | D8: 112 | E8: 25312 | F8: Yüksek
A9: 2026-07 | B9: M001 | C9: AKEVLER | D9: 112 | E9: 19824 | F9: Düşük
A10: 2026-08 | B10: M001 | C10: AKEVLER | D10: 108 | E10: 15336 | F10: Orta
A11: 2026-09 | B11: M001 | C11: AKEVLER | D11: 56 | E11: 8288 | F11: Yüksek
A12: 2026-10 | B12: M001 | C12: AKEVLER | D12: 126 | E12: 19782 | F12: Yüksek
A13: 2026-11 | B13: M001 | C13: AKEVLER | D13: 26 | E13: 4186 | F13: Düşük
A14: 2026-12 | B14: M001 | C14: AKEVLER | D14: 120 | E14: 17280 | F14: Yüksek
... A638: 2026-12 | B638: M057 | C638: BUCA2 | D638: 65 | E638: 11700 | F638: Yüksek

Sheet Devamsızlık
A1: DEVAMSIZLIK
A2: Ay | B2: MagazaID | C2: Mağaza | D2: Devamsızlık Gün | E2: Rapor Gün | F2: Fiili Kayıp FTE
A3: 2026-01 | B3: M001 | C3: AKEVLER | D3: 9 | E3: 2 | F3: 0.5
A4: 2026-02 | B4: M001 | C4: AKEVLER | D4: 17 | E4: 7 | F4: 0.9
A5: 2026-03 | B5: M001 | C5: AKEVLER | D5: 7 | E5: 0 | F5: 0.4
A6: 2026-04 | B6: M001 | C6: AKEVLER | D6: 12 | E6: 5 | F6: 0.7
A7: 2026-05 | B7: M001 | C7: AKEVLER | D7: 13 | E7: 7 | F7: 0.7
A8: 2026-06 | B8: M001 | C8: AKEVLER | D8: 19 | E8: 8 | F8: 1.1
A9: 2026-07 | B9: M001 | C9: AKEVLER | D9: 5 | E9: 8 | F9: 0.3
A10: 2026-08 | B10: M001 | C10: AKEVLER | D10: 18 | E10: 10 | F10: 1
A11: 2026-09 | B11: M001 | C11: AKEVLER | D11: 3 | E11: 6 | F11: 0.2
A12: 2026-10 | B12: M001 | C12: AKEVLER | D12: 11 | E12: 0 | F12: 0.6
A13: 2026-11 | B13: M001 | C13: AKEVLER | D13: 11 | E13: 5 | F13: 0.6
A14: 2026-12 | B14: M001 | C14: AKEVLER | D14: 0 | E14: 10 | F14: 0
... A638: 2026-12 | B638: M057 | C638: BUCA2 | D638: 15 | E638: 0 | F638: 0.8

Sheet Eğitim
A1: EĞİTİM
A2: Ay | B2: MagazaID | C2: Mağaza | D2: Eğitim Saat | E2: Katılımcı | F2: Eğitim Etki
A3: 2026-01 | B3: M001 | C3: AKEVLER | D3: 197 | E3: 10 | F3: İyi
A4: 2026-02 | B4: M001 | C4: AKEVLER | D4: 11 | E4: 6 | F4: Zayıf
A5: 2026-03 | B5: M001 | C5: AKEVLER | D5: 168 | E5: 21 | F5: İyi
A6: 2026-04 | B6: M001 | C6: AKEVLER | D6: 102 | E6: 5 | F6: Orta
A7: 2026-05 | B7: M001 | C7: AKEVLER | D7: 85 | E7: 12 | F7: Zayıf
A8: 2026-06 | B8: M001 | C8: AKEVLER | D8: 51 | E8: 32 | F8: Zayıf
A9: 2026-07 | B9: M001 | C9: AKEVLER | D9: 127 | E9: 32 | F9: Orta
A10: 2026-08 | B10: M001 | C10: AKEVLER | D10: 163 | E10: 5 | F10: Orta
A11: 2026-09 | B11: M001 | C11: AKEVLER | D11: 71 | E11: 33 | F11: Zayıf
A12: 2026-10 | B12: M001 | C12: AKEVLER | D12: 85 | E12: 6 | F12: Orta
A13: 2026-11 | B13: M001 | C13: AKEVLER | D13: 131 | E13: 18 | F13: Zayıf
A14: 2026-12 | B14: M001 | C14: AKEVLER | D14: 48 | E14: 14 | F14: Orta
... A638: 2026-12 | B638: M057 | C638: BUCA2 | D638: 147 | E638: 8 | F638: Zayıf

Sheet İzin
A1: İZİN
A2: Ay | B2: MagazaID | C2: Mağaza | D2: Yıllık İzin Gün | E2: Ücretsiz İzin Gün | F2: Mazeret İzin Gün
A3: 2026-01 | B3: M001 | C3: AKEVLER | D3: 24 | E3: 4 | F3: 5
A4: 2026-02 | B4: M001 | C4: AKEVLER | D4: 24 | E4: 6 | F4: 2
A5: 2026-03 | B5: M001 | C5: AKEVLER | D5: 26 | E5: 6 | F5: 2
A6: 2026-04 | B6: M001 | C6: AKEVLER | D6: 29 | E6: 5 | F6: 7
A7: 2026-05 | B7: M001 | C7: AKEVLER | D7: 19 | E7: 0 | F7: 6
A8: 2026-06 | B8: M001 | C8: AKEVLER | D8: 9 | E8: 6 | F8: 8
A9: 2026-07 | B9: M001 | C9: AKEVLER | D9: 15 | E9: 4 | F9: 2
A10: 2026-08 | B10: M001 | C10: AKEVLER | D10: 33 | E10: 3 | F10: 7
A11: 2026-09 | B11: M001 | C11: AKEVLER | D11: 26 | E11: 3 | F11: 4
A12: 2026-10 | B12: M001 | C12: AKEVLER | D12: 2 | E12: 7 | F12: 2
A13: 2026-11 | B13: M001 | C13: AKEVLER | D13: 28 | E13: 8 | F13: 2
A14: 2026-12 | B14: M001 | C14: AKEVLER | D14: 17 | E14: 0 | F14: 3
... A638: 2026-12 | B638: M057 | C638: BUCA2 | D638: 17 | E638: 2 | F638: 5

Sheet Performans
A1: PERFORMANS
A2: Ay | B2: MagazaID | C2: Mağaza | D2: Operasyon Puanı | E2: Yönetici Puanı | F2: Müşteri Deneyimi
A3: 2026-01 | B3: M001 | C3: AKEVLER | D3: 85 | E3: 69 | F3: 98
A4: 2026-02 | B4: M001 | C4: AKEVLER | D4: 66 | E4: 87 | F4: 92
A5: 2026-03 | B5: M001 | C5: AKEVLER | D5: 75 | E5: 61 | F5: 82
A6: 2026-04 | B6: M001 | C6: AKEVLER | D6: 98 | E6: 80 | F6: 83
A7: 2026-05 | B7: M001 | C7: AKEVLER | D7: 78 | E7: 95 | F7: 80
A8: 2026-06 | B8: M001 | C8: AKEVLER | D8: 84 | E8: 62 | F8: 98
A9: 2026-07 | B9: M001 | C9: AKEVLER | D9: 77 | E9: 89 | F9: 87
A10: 2026-08 | B10: M001 | C10: AKEVLER | D10: 86 | E10: 92 | F10: 76
